Workbook

Sheet LiD Calculator
A1: SELECT FIGHTER | K1: Decals
A2: FIGHTER CLASS | C2: Shooter | K2: Name | O2: A GRP | P2: C GRP | Q2: REQ WEP | R2: REQ DAM TYPE | S2: REQ ELE | T2: REQ FAC | U2: ATK * | V2: ATK 2 * | W2: HS * | X2: CRIT % | Y2: CRIT * | Z2: EXPLOSIVE | AA2: APPLICABLE MUL
A3: GRADE | C3: 8 | J3: 1 | K3: Professional Cosplayer | O3: =_xlfn.XLOOKUP(K3,Decals!$A$3:$A$178,Decals!$B$3:$B$178,0) -> 3 | P3: =_xlfn.XLOOKUP(K3,Decals!$A$3:$A$178,Decals!$C$3:$C$178,0) -> 0 | Q3: =_xlfn.XLOOKUP(K3,Decals!$A$3:$A$178,Decals!$D$3:$D$178,0) -> 0 | R3: =_xlfn.XLOOKUP(K3,Decals!$A$3:$A$178,Decals!$E$3:$E$178,0) -> 0 | S3: =_xlfn.XLOOKUP(K3,Decals!$A$3:$A$178,Decals!$F$3:$F$178,0) -> 0 | T3: =_xlfn.XLOOKUP(K3,Decals!$A$3:$A$178,Decals!$G$3:$G$178,0) -> 0 | U3: =_xlfn.XLOOKUP(K3,Decals!$A$3:$A$178,Decals!$H$3:$H$178,0) -> 20 | V3: =_xlfn.XLOOKUP(K3,Decals!$A$3:$A$178,Decals!$I$3:$I$178,0) -> 0 | W3: =_xlfn.XLOOKUP(K3,Decals!$A$3:$A$178,Decals!$J$3:$J$178,0) -> 0 | X3: =_xlfn.XLOOKUP(K3,Decals!$A$3:$A$178,Decals!$K$3:$K$178,0) -> 20 | Y3: =_xlfn.XLOOKUP(K3,Decals!$A$3:$A$178,Decals!$L$3:$L$178,0) -> 0 | Z3: =_xlfn.XLOOKUP(K3,Decals!$A$3:$A$178,Decals!$M$3:$M$178,0) -> 0 | AA3: =IF( AND( OR(ISNUMBER(SEARCH($C$17,R3)),R3=0), OR(ISNUMBER(SEARCH($C$18,S3)),S3=0), OR(ISNUMBER(SEARCH($C$16,Q3)),Q3=0) ), U3,0) -> 20
A4: HP | B4: STM | C4: STR | D4: DEX | E4: VIT | F4: LUK | G4: BASE CRIT % | J4: 2 | K4: Joker | O4: =_xlfn.XLOOKUP(K4,Decals!$A$3:$A$178,Decals!$B$3:$B$178,0) -> 1 | P4: =_xlfn.XLOOKUP(K4,Decals!$A$3:$A$178,Decals!$C$3:$C$178,0) -> 0 | Q4: =_xlfn.XLOOKUP(K4,Decals!$A$3:$A$178,Decals!$D$3:$D$178,0) -> 0 | R4: =_xlfn.XLOOKUP(K4,Decals!$A$3:$A$178,Decals!$E$3:$E$178,0) -> 0 | S4: =_xlfn.XLOOKUP(K4,Decals!$A$3:$A$178,Decals!$F$3:$F$178,0) -> 0 | T4: =_xlfn.XLOOKUP(K4,Decals!$A$3:$A$178,Decals!$G$3:$G$178,0) -> 0 | U4: =_xlfn.XLOOKUP(K4,Decals!$A$3:$A$178,Decals!$H$3:$H$178,0) -> 15 | V4: =_xlfn.XLOOKUP(K4,Decals!$A$3:$A$178,Decals!$I$3:$I$178,0) -> 0 | W4: =_xlfn.XLOOKUP(K4,Decals!$A$3:$A$178,Decals!$J$3:$J$178,0) -> 0 | X4: =_xlfn.XLOOKUP(K4,Decals!$A$3:$A$178,Decals!$K$3:$K$178,0) -> 0 | Y4: =_xlfn.XLOOKUP(K4,Decals!$A$3:$A$178,Decals!$L$3:$L$178,0) -> 0 | Z4: =_xlfn.XLOOKUP(K4,Decals!$A$3:$A$178,Decals!$M$3:$M$178,0) -> 0 | AA4: =IF( AND( OR(ISNUMBER(SEARCH($C$17,R4)),R4=0), OR(ISNUMBER(SEARCH($C$18,S4)),S4=0), OR(ISNUMBER(SEARCH($C$16,Q4)),Q4=0) ), U4,0) -> 15
A5: {=INDEX(Fighters!$B$3:$AW$10, MATCH('LiD Calculator'!$C$3,Fighters!$A$3:$A$10,0), MATCH('LiD Calculator'!$C$2,Fighters!$B$1:$AW$1,0) + MATCH(A4,Fighters!$B$2:$G$2,0) - 1 )} -> 20295 | B5: {=INDEX(Fighters!$B$3:$AW$10, MATCH('LiD Calculator'!$C$3,Fighters!$A$3:$A$10,0), MATCH('LiD Calculator'!$C$2,Fighters!$B$1:$AW$1,0) + MATCH(B4,Fighters!$B$2:$G$2,0) - 1 )} -> 282 | C5: {=INDEX(Fighters!$B$3:$AW$10, MATCH('LiD Calculator'!$C$3,Fighters!$A$3:$A$10,0), MATCH('LiD Calculator'!$C$2,Fighters!$B$1:$AW$1,0) + MATCH(C4,Fighters!$B$2:$G$2,0) - 1 )} -> 206 | D5: {=INDEX(Fighters!$B$3:$AW$10, MATCH('LiD Calculator'!$C$3,Fighters!$A$3:$A$10,0), MATCH('LiD Calculator'!$C$2,Fighters!$B$1:$AW$1,0) + MATCH(D4,Fighters!$B$2:$G$2,0) - 1 )} -> 540 | E5: {=INDEX(Fighters!$B$3:$AW$10, MATCH('LiD Calculator'!$C$3,Fighters!$A$3:$A$10,0), MATCH('LiD Calculator'!$C$2,Fighters!$B$1:$AW$1,0) + MATCH(E4,Fighters!$B$2:$G$2,0) - 1 )} -> 174 | F5: {=INDEX(Fighters!$B$3:$AW$10, MATCH('LiD Calculator'!$C$3,Fighters!$A$3:$A$10,0), MATCH('LiD Calculator'!$C$2,Fighters!$B$1:$AW$1,0) + MATCH(F4,Fighters!$B$2:$G$2,0) - 1 )} -> 53 | G5: =_xlfn.XLOOKUP(F5,Lists!I2:I192,Lists!J2:J192) -> 35.5 | J5: 3 | K5: Barbarian | O5: =_xlfn.XLOOKUP(K5,Decals!$A$3:$A$178,Decals!$B$3:$B$178,0) -> 7 | P5: =_xlfn.XLOOKUP(K5,Decals!$A$3:$A$178,Decals!$C$3:$C$178,0) -> 0 | Q5: =_xlfn.XLOOKUP(K5,Decals!$A$3:$A$178,Decals!$D$3:$D$178,0) -> 0 | R5: =_xlfn.XLOOKUP(K5,Decals!$A$3:$A$178,Decals!$E$3:$E$178,0) -> 0 | S5: =_xlfn.XLOOKUP(K5,Decals!$A$3:$A$178,Decals!$F$3:$F$178,0) -> 0 | T5: =_xlfn.XLOOKUP(K5,Decals!$A$3:$A$178,Decals!$G$3:$G$178,0) -> 0 | U5: =_xlfn.XLOOKUP(K5,Decals!$A$3:$A$178,Decals!$H$3:$H$178,0) -> 20 | V5: =_xlfn.XLOOKUP(K5,Decals!$A$3:$A$178,Decals!$I$3:$I$178,0) -> 0 | W5: =_xlfn.XLOOKUP(K5,Decals!$A$3:$A$178,Decals!$J$3:$J$178,0) -> 0 | X5: =_xlfn.XLOOKUP(K5,Decals!$A$3:$A$178,Decals!$K$3:$K$178,0) -> 0 | Y5: =_xlfn.XLOOKUP(K5,Decals!$A$3:$A$178,Decals!$L$3:$L$178,0) -> 0 | Z5: =_xlfn.XLOOKUP(K5,Decals!$A$3:$A$178,Decals!$M$3:$M$178,0) -> 0 | AA5: =IF( AND( OR(ISNUMBER(SEARCH($C$17,R5)),R5=0), OR(ISNUMBER(SEARCH($C$18,S5)),S5=0), OR(ISNUMBER(SEARCH($C$16,Q5)),Q5=0) ), U5,0) -> 20
J6: 4 | K6: Critical Attack | O6: =_xlfn.XLOOKUP(K6,Decals!$A$3:$A$178,Decals!$B$3:$B$178,0) -> 0 | P6: =_xlfn.XLOOKUP(K6,Decals!$A$3:$A$178,Decals!$C$3:$C$178,0) -> 2 | Q6: =_xlfn.XLOOKUP(K6,Decals!$A$3:$A$178,Decals!$D$3:$D$178,0) -> 0 | R6: =_xlfn.XLOOKUP(K6,Decals!$A$3:$A$178,Decals!$E$3:$E$178,0) -> 0 | S6: =_xlfn.XLOOKUP(K6,Decals!$A$3:$A$178,Decals!$F$3:$F$178,0) -> 0 | T6: =_xlfn.XLOOKUP(K6,Decals!$A$3:$A$178,Decals!$G$3:$G$178,0) -> 0 | U6: =_xlfn.XLOOKUP(K6,Decals!$A$3:$A$178,Decals!$H$3:$H$178,0) -> 0 | V6: =_xlfn.XLOOKUP(K6,Decals!$A$3:$A$178,Decals!$I$3:$I$178,0) -> 0 | W6: =_xlfn.XLOOKUP(K6,Decals!$A$3:$A$178,Decals!$J$3:$J$178,0) -> 0 | X6: =_xlfn.XLOOKUP(K6,Decals!$A$3:$A$178,Decals!$K$3:$K$178,0) -> 0 | Y6: =_xlfn.XLOOKUP(K6,Decals!$A$3:$A$178,Decals!$L$3:$L$178,0) -> 30 | Z6: =_xlfn.XLOOKUP(K6,Decals!$A$3:$A$178,Decals!$M$3:$M$178,0) -> 0 | AA6: =IF( AND( OR(ISNUMBER(SEARCH($C$17,R6)),R6=0), OR(ISNUMBER(SEARCH($C$18,S6)),S6=0), OR(ISNUMBER(SEARCH($C$16,Q6)),Q6=0) ), U6,0) -> 0
A7: OPTIONAL FUNSHOTS | J7: 5 | K7: Assault Rifle Addict | O7: =_xlfn.XLOOKUP(K7,Decals!$A$3:$A$178,Decals!$B$3:$B$178,0) -> 4 | P7: =_xlfn.XLOOKUP(K7,Decals!$A$3:$A$178,Decals!$C$3:$C$178,0) -> 0 | Q7: =_xlfn.XLOOKUP(K7,Decals!$A$3:$A$178,Decals!$D$3:$D$178,0) -> Assault Rifle | R7: =_xlfn.XLOOKUP(K7,Decals!$A$3:$A$178,Decals!$E$3:$E$178,0) -> 0 | S7: =_xlfn.XLOOKUP(K7,Decals!$A$3:$A$178,Decals!$F$3:$F$178,0) -> 0 | T7: =_xlfn.XLOOKUP(K7,Decals!$A$3:$A$178,Decals!$G$3:$G$178,0) -> 0 | U7: =_xlfn.XLOOKUP(K7,Decals!$A$3:$A$178,Decals!$H$3:$H$178,0) -> 30 | V7: =_xlfn.XLOOKUP(K7,Decals!$A$3:$A$178,Decals!$I$3:$I$178,0) -> 0 | W7: =_xlfn.XLOOKUP(K7,Decals!$A$3:$A$178,Decals!$J$3:$J$178,0) -> 0 | X7: =_xlfn.XLOOKUP(K7,Decals!$A$3:$A$178,Decals!$K$3:$K$178,0) -> 0 | Y7: =_xlfn.XLOOKUP(K7,Decals!$A$3:$A$178,Decals!$L$3:$L$178,0) -> 0 | Z7: =_xlfn.XLOOKUP(K7,Decals!$A$3:$A$178,Decals!$M$3:$M$178,0) -> 0 | AA7: =IF( AND( OR(ISNUMBER(SEARCH($C$17,R7)),R7=0), OR(ISNUMBER(SEARCH($C$18,S7)),S7=0), OR(ISNUMBER(SEARCH($C$16,Q7)),Q7=0) ), U7,0) -> 30
A8: SLASH | B8: BLUNT | C8: PIERCE | D8: HEAD | E8: BODY | F8: LEG | J8: 6 | K8: Golden Gym | O8: =_xlfn.XLOOKUP(K8,Decals!$A$3:$A$178,Decals!$B$3:$B$178,0) -> 1 | P8: =_xlfn.XLOOKUP(K8,Decals!$A$3:$A$178,Decals!$C$3:$C$178,0) -> 0 | Q8: =_xlfn.XLOOKUP(K8,Decals!$A$3:$A$178,Decals!$D$3:$D$178,0) -> 0 | R8: =_xlfn.XLOOKUP(K8,Decals!$A$3:$A$178,Decals!$E$3:$E$178,0) -> 0 | S8: =_xlfn.XLOOKUP(K8,Decals!$A$3:$A$178,Decals!$F$3:$F$178,0) -> 0 | T8: =_xlfn.XLOOKUP(K8,Decals!$A$3:$A$178,Decals!$G$3:$G$178,0) -> 0 | U8: =_xlfn.XLOOKUP(K8,Decals!$A$3:$A$178,Decals!$H$3:$H$178,0) -> 30 | V8: =_xlfn.XLOOKUP(K8,Decals!$A$3:$A$178,Decals!$I$3:$I$178,0) -> 0 | W8: =_xlfn.XLOOKUP(K8,Decals!$A$3:$A$178,Decals!$J$3:$J$178,0) -> 0 | X8: =_xlfn.XLOOKUP(K8,Decals!$A$3:$A$178,Decals!$K$3:$K$178,0) -> 0 | Y8: =_xlfn.XLOOKUP(K8,Decals!$A$3:$A$178,Decals!$L$3:$L$178,0) -> 0 | Z8: =_xlfn.XLOOKUP(K8,Decals!$A$3:$A$178,Decals!$M$3:$M$178,0) -> 0 | AA8: =IF( AND( OR(ISNUMBER(SEARCH($C$17,R8)),R8=0), OR(ISNUMBER(SEARCH($C$18,S8)),S8=0), OR(ISNUMBER(SEARCH($C$16,Q8)),Q8=0) ), U8,0) -> 30
A9: 0 | B9: 0 | C9: 0 | D9: 0 | E9: 0 | F9: 0 | J9: 7 | K9: Five-leaf Clover | O9: =_xlfn.XLOOKUP(K9,Decals!$A$3:$A$178,Decals!$B$3:$B$178,0) -> 0 | P9: =_xlfn.XLOOKUP(K9,Decals!$A$3:$A$178,Decals!$C$3:$C$178,0) -> 0 | Q9: =_xlfn.XLOOKUP(K9,Decals!$A$3:$A$178,Decals!$D$3:$D$178,0) -> 0 | R9: =_xlfn.XLOOKUP(K9,Decals!$A$3:$A$178,Decals!$E$3:$E$178,0) -> 0 | S9: =_xlfn.XLOOKUP(K9,Decals!$A$3:$A$178,Decals!$F$3:$F$178,0) -> 0 | T9: =_xlfn.XLOOKUP(K9,Decals!$A$3:$A$178,Decals!$G$3:$G$178,0) -> 0 | U9: =_xlfn.XLOOKUP(K9,Decals!$A$3:$A$178,Decals!$H$3:$H$178,0) -> 0 | V9: =_xlfn.XLOOKUP(K9,Decals!$A$3:$A$178,Decals!$I$3:$I$178,0) -> 0 | W9: =_xlfn.XLOOKUP(K9,Decals!$A$3:$A$178,Decals!$J$3:$J$178,0) -> 0 | X9: =_xlfn.XLOOKUP(K9,Decals!$A$3:$A$178,Decals!$K$3:$K$178,0) -> 20 | Y9: =_xlfn.XLOOKUP(K9,Decals!$A$3:$A$178,Decals!$L$3:$L$178,0) -> 0 | Z9: =_xlfn.XLOOKUP(K9,Decals!$A$3:$A$178,Decals!$M$3:$M$178,0) -> 0 | AA9: =IF( AND( OR(ISNUMBER(SEARCH($C$17,R9)),R9=0), OR(ISNUMBER(SEARCH($C$18,S9)),S9=0), OR(ISNUMBER(SEARCH($C$16,Q9)),Q9=0) ), U9,0) -> 0
J10: 8 | K10: Serial Killer | O10: =_xlfn.XLOOKUP(K10,Decals!$A$3:$A$178,Decals!$B$3:$B$178,0) -> 1 | P10: =_xlfn.XLOOKUP(K10,Decals!$A$3:$A$178,Decals!$C$3:$C$178,0) -> 0 | Q10: =_xlfn.XLOOKUP(K10,Decals!$A$3:$A$178,Decals!$D$3:$D$178,0) -> 0 | R10: =_xlfn.XLOOKUP(K10,Decals!$A$3:$A$178,Decals!$E$3:$E$178,0) -> 0 | S10: =_xlfn.XLOOKUP(K10,Decals!$A$3:$A$178,Decals!$F$3:$F$178,0) -> 0 | T10: =_xlfn.XLOOKUP(K10,Decals!$A$3:$A$178,Decals!$G$3:$G$178,0) -> 0 | U10: =_xlfn.XLOOKUP(K10,Decals!$A$3:$A$178,Decals!$H$3:$H$178,0) -> 100 | V10: =_xlfn.XLOOKUP(K10,Decals!$A$3:$A$178,Decals!$I$3:$I$178,0) -> 0 | W10: =_xlfn.XLOOKUP(K10,Decals!$A$3:$A$178,Decals!$J$3:$J$178,0) -> 0 | X10: =_xlfn.XLOOKUP(K10,Decals!$A$3:$A$178,Decals!$K$3:$K$178,0) -> 0 | Y10: =_xlfn.XLOOKUP(K10,Decals!$A$3:$A$178,Decals!$L$3:$L$178,0) -> 0 | Z10: =_xlfn.XLOOKUP(K10,Decals!$A$3:$A$178,Decals!$M$3:$M$178,0) -> 0 | AA10: =IF( AND( OR(ISNUMBER(SEARCH($C$17,R10)),R10=0), OR(ISNUMBER(SEARCH($C$18,S10)),S10=0), OR(ISNUMBER(SEARCH($C$16,Q10)),Q10=0) ), U10,0) -> 100
A11: SELECT WEAPON | J11: 9 | O11: =_xlfn.XLOOKUP(K11,Decals!$A$3:$A$178,Decals!$B$3:$B$178,0) -> 0 | P11: =_xlfn.XLOOKUP(K11,Decals!$A$3:$A$178,Decals!$C$3:$C$178,0) -> 0 | Q11: =_xlfn.XLOOKUP(K11,Decals!$A$3:$A$178,Decals!$D$3:$D$178,0) -> 0 | R11: =_xlfn.XLOOKUP(K11,Decals!$A$3:$A$178,Decals!$E$3:$E$178,0) -> 0 | S11: =_xlfn.XLOOKUP(K11,Decals!$A$3:$A$178,Decals!$F$3:$F$178,0) -> 0 | T11: =_xlfn.XLOOKUP(K11,Decals!$A$3:$A$178,Decals!$G$3:$G$178,0) -> 0 | U11: =_xlfn.XLOOKUP(K11,Decals!$A$3:$A$178,Decals!$H$3:$H$178,0) -> 0 | V11: =_xlfn.XLOOKUP(K11,Decals!$A$3:$A$178,Decals!$I$3:$I$178,0) -> 0 | W11: =_xlfn.XLOOKUP(K11,Decals!$A$3:$A$178,Decals!$J$3:$J$178,0) -> 0 | X11: =_xlfn.XLOOKUP(K11,Decals!$A$3:$A$178,Decals!$K$3:$K$178,0) -> 0 | Y11: =_xlfn.XLOOKUP(K11,Decals!$A$3:$A$178,Decals!$L$3:$L$178,0) -> 0 | Z11: =_xlfn.XLOOKUP(K11,Decals!$A$3:$A$178,Decals!$M$3:$M$178,0) -> 0 | AA11: =IF( AND( OR(ISNUMBER(SEARCH($C$17,R11)),R11=0), OR(ISNUMBER(SEARCH($C$18,S11)),S11=0), OR(ISNUMBER(SEARCH($C$16,Q11)),Q11=0) ), U11,0) -> 0
A12: WEAPON | C12: Assault Rifle RE
A13: TIER | C13: 9 | K13: ATK DECAL GROUP SUMS | Z13: FINAL ATK MULTIPLIER
K14: 1 | L14: 2 | M14: 3 | N14: 4 | O14: 5 | P14: 6 | Q14: 7 | R14: 8 | S14: 9 | T14: 10 | U14: 11 | V14: 12 | W14: 13 | X14: 14 | Y14: 15
A15: ATK | C15: =INDEX(Weapons!$O$2:$U$74, MATCH('LiD Calculator'!$C$12:$G$12,Weapons!$A$2:$A$74, 0), MATCH('LiD Calculator'!$C$13:$G$13,Weapons!$O$1:$U$1, 0) ) -> 3187 | K15: =SUMIFS($AA$3:$AA$11,$O$3:$O$11,1) / 100 + 1 -> 2.45 | L15: =SUMIFS($AA$3:$AA$11,$O$3:$O$11,2) / 100 + 1 -> 1 | M15: =SUMIFS($AA$3:$AA$11,$O$3:$O$11,3) / 100 + 1 -> 1.2 | N15: =SUMIFS($AA$3:$AA$11,$O$3:$O$11,4) / 100 + 1 -> 1.3 | O15: =SUMIFS($AA$3:$AA$11,$O$3:$O$11,5) / 100 + 1 -> 1 | P15: =SUMIFS($AA$3:$AA$11,$O$3:$O$11,6) / 100 + 1 -> 1 | Q15: =SUMIFS($AA$3:$AA$11,$O$3:$O$11,7) / 100 + 1 -> 1.2 | R15: =SUMIFS($AA$3:$AA$11,$O$3:$O$11,8) / 100 + 1 -> 1 | S15: =SUMIFS($AA$3:$AA$11,$O$3:$O$11,9) / 100 + 1 -> 1 | T15: =SUMIFS($AA$3:$AA$11,$O$3:$O$11,10) / 100 + 1 -> 1 | U15: =SUMIFS($AA$3:$AA$11,$O$3:$O$11,11) / 100 + 1 -> 1 | V15: =SUMIFS($AA$3:$AA$11,$O$3:$O$11,12) / 100 + 1 -> 1 | W15: =SUMIFS($AA$3:$AA$11,$O$3:$O$11,13) / 100 + 1 -> 1 | X15: =SUMIFS($AA$3:$AA$11,$O$3:$O$11,14) / 100 + 1 -> 1 | Y15: =SUMIFS($AA$3:$AA$11,$O$3:$O$11,15) / 100 + 1 -> 1 | Z15: =K15 * L15 * M15 * N15 * O15 * P15 * Q15 * R15 * S15 * T15 * U15 * V15 * W15 * X15 * Y15 -> 4.5864
A16: WEAPON TYPE | C16: =_xlfn.XLOOKUP(C12,Table1[Name],Table1[Type]) -> Assault Rifle
A17: RAW TYPE | C17: =_xlfn.XLOOKUP(C16,Weapons!A2:A74,Weapons!I2:I74) -> Piercing | E17: % | F17: =_xlfn.XLOOKUP(C12,Table1[Name],Table1[RAW %]) -> 100 | K17: EXPLOSIVE MULTIPLIER | N17: HEADSHOT MULTIPLIER
A18: ELEMENT TYPE | C18: =_xlfn.XLOOKUP(C12,Table1[Name],Table1[E TYPE]) -> 0 | E18: % | F18: =_xlfn.XLOOKUP(C12,Table1[Name], Table1[E %]) -> 0 | K18: =SUM(Y3:Y11)/100+1 -> 1.3 | N18: =C22+(SUM(W3:W11) / 100 + 1) -> 2.5
A19: STAT REQ | C19: =_xlfn.XLOOKUP(C12,Table1[Name], Table1[REQ]) -> DEX
A20: STR % | C20: =_xlfn.XLOOKUP(C12,Table1[Name],Table1[STR %]) -> 000 | K20: CRITICAL CHANCE | N20: CRIT DMG MULTIPLIER
A21: DEX % | C21: =_xlfn.XLOOKUP(C12,Table1[Name],Table1[DEX %]) -> 100 | K21: =IF( SUM(X3:X11,G5)<=99.9, SUM(X3:X11,G5), 99.9) -> 75.5 | N21: =SUM(Y3:Y11)/100+1 -> 1.3
A22: HEADSHOT MULTI | C22: =_xlfn.XLOOKUP(C12,Table1[Name],Table1[HEADSHOT]) -> 1.5
K23: FINAL NON-CRIT ATTACK | O23: =SUM(C15*Z15) -> 14616.857
K24: FINAL CRIT ATTACK | O24: =SUM(O23 * (1.5 * N21)) -> 28502.871
K25: FINAL AVG ATTACK | O25: =O23 + ((O24 - O23) * (K21 / 100)) -> 25100.797
K26: FINAL NON-CRIT HEADSHOT | O26: =O23 * N18 -> 36542.142
K27: FINAL CRIT HEADSHOT | O27: =O26 * (1.5 * N21) -> 71257.177

Sheet Decals
A1: NAME | B1: A GRP | C1: C GRP | D1: REQ WEP | E1: REQ DAM TYPE | F1: REQ ELE | G1: REQ FAC | H1: ATK * | I1: ATK 2 * | J1: HS * | K1: CRIT % | L1: CRIT * | M1: EXPLOSIVE | N1: RAGE DMG * | O1: HP <= 15% | P1: HP 100% | Q1: DOWN ATK * | R1: REQS | S1: Comments
A3: Super Hero | B3: 1 | P3: 15
A4: Legendary Hero | B4: 1 | P4: 30
A5: Bull | B5: 1 | O5: 30
A6: Raging Bull | B6: 1 | O6: 60
A7: Serial Killer | B7: 1 | H7: 100
A8: Dumbbell | B8: 1 | H8: 7
A9: Barbell | B9: 1 | H9: 15
A10: Judge's Gavel | Q10: 100
A11: One Shot One Kill | B11: 11 | J11: 70
A12: Barbarian | B12: 7 | H12: 20
A13: Dual Wielding Master | B13: 6 | H13: 10
A14: Master Builder | B14: 3 | G14: DOD | H14: 7
A15: Drill Sergeant | B15: 3 | G15: WE | H15: 7
A16: Wizard | B16: 3 | G16: CW | H16: 7
A17: Medalist | B17: 3 | G17: MILK | H17: 7
A18: Samurai | B18: 5 | E18: Slash | H18: 10
A19: Slugger | B19: 5 | E19: Blunt | H19: 10
A20: Firestarter | B20: 5 | F20: Fire | H20: 10
A21: Electrifier | B21: 5 | F21: Electric | H21: 10
A22: Hornet | B22: 5 | F22: Poison | H22: 10
A23: Giant Killer | B23: 8 | H23: 30
A24: Four-leaf Clover | K24: 10
A25: Five-leaf Clover | K25: 20
A26: Superalloy | B26: 9 | H26: 20
A27: Dengeki Playstation | Q27: 10
A28: Self-Defense | H28: 50
A29: Hammer Addict | B29: 4 | D29: Hammer | H29: 30
A30: Machete Addict | B30: 4 | D30: Machete | H30: 30
A31: Assault Rifle Addict | B31: 4 | D31: Assault Rifle | H31: 30
A32: Saber Addict | B32: 4 | D32: Saber | H32: 30
A33: Fireworks Addict | B33: 4 | D33: Fireworks | H33: 30
A34: Trump Card | H34: 20
A35: Iron Addict | B35: 4 | D35: Iron | H35: 30
A36: Crossbow Addict | B36: 4 | D36: Crossbow | H36: 30
A37: Katana Addict | B37: 4 | D37: Katana | H37: 30
A38: Hockey Addict | B38: 4 | D38: Hockey Stick | H38: 30
A39: Panther Mode | H39: 5
A40: Jupiter Style | E40: Slash, Blunt | H40: 10
A41: Durga Angel | K41: 15
...

Sheet Fighters
B1: ALL-ROUNDER | H1: STRIKER | N1: DEFENDER | T1: ATTACKER | Z1: SHOOTER | AF1: COLLECTOR | AL1: SKILL MASTER | AR1: LUCKY STAR
A2: GRADE | B2: HP | C2: STM | D2: STR | E2: DEX | F2: VIT | G2: LUK | H2: HP | I2: STM | J2: STR | K2: DEX | L2: VIT | M2: LUK | N2: HP | O2: STM | P2: STR | Q2: DEX | R2: VIT | S2: LUK | T2: HP | U2: STM | V2: STR | W2: DEX | X2: VIT | Y2: LUK | Z2: HP | AA2: STM | AB2: STR | AC2: DEX | AD2: VIT | AE2: LUK | AF2: HP | AG2: STM | AH2: STR | AI2: DEX | AJ2: VIT | AK2: LUK | AL2: HP | AM2: STM | AN2: STR | AO2: DEX | AP2: VIT | AQ2: LUK | AR2: HP | AS2: STM | AT2: STR | AU2: DEX | AV2: VIT | AW2: LUK
A3: 1 | B3: 350 | C3: 226 | D3: 30 | E3: 30 | F3: 25 | G3: 15 | H3: 440 | I3: 203 | J3: 45 | K3: 20 | L3: 25 | M3: 15 | N3: 510 | O3: 249 | P3: 20 | Q3: 20 | R3: 40 | S3: 15 | T3: 220 | U3: 203 | V3: 45 | W3: 45 | X3: 20 | Y3: 15 | Z3: 310 | AA3: 190 | AB3: 30 | AC3: 45 | AD3: 25 | AE3: 15 | AF3: 490 | AG3: 231 | AH3: 25 | AI3: 25 | AJ3: 25 | AK3: 20 | AL3: 330 | AM3: 221 | AN3: 25 | AO3: 25 | AP3: 20 | AQ3: 15 | AR3: 330 | AS3: 226 | AT3: 25 | AU3: 25 | AV3: 25 | AW3: 30
A4: 2 | B4: 475 | C4: 243 | D4: 56 | E4: 56 | F4: 40 | G4: 20 | H4: 599 | I4: 216 | J4: 80 | K4: 31 | L4: 40 | M4: 20 | N4: 695 | O4: 279 | P4: 38 | Q4: 38 | R4: 65 | S4: 20 | T4: 289 | U4: 213 | V4: 80 | W4: 80 | X4: 30 | Y4: 20 | Z4: 454 | AA4: 207 | AB4: 56 | AC4: 74 | AD4: 40 | AE4: 20 | AF4: 850 | AG4: 254 | AH4: 45 | AI4: 45 | AJ4: 39 | AK4: 30 | AL4: 418 | AM4: 231 | AN4: 45 | AO4: 45 | AP4: 30 | AQ4: 20 | AR4: 418 | AS4: 240 | AT4: 45 | AU4: 45 | AV4: 39 | AW4: 47
A5: 3 | B5: 918 | C5: 262 | D5: 86 | E5: 86 | F5: 58 | G5: 26 | H5: 1158 | I5: 230 | J5: 120 | K5: 44 | L5: 58 | M5: 26 | N5: 1314 | O5: 312 | P5: 58 | Q5: 58 | R5: 95 | S5: 26 | T5: 538 | U5: 223 | V5: 120 | W5: 120 | X5: 42 | Y5: 26 | Z5: 902 | AA5: 226 | AB5: 86 | AC5: 129 | AD5: 58 | AE5: 26 | AF5: 1320 | AG5: 280 | AH5: 68 | AI5: 68 | AJ5: 56 | AK5: 42 | AL5: 788 | AM5: 241 | AN5: 68 | AO5: 68 | AP5: 42 | AQ5: 26 | AR5: 788 | AS5: 255 | AT5: 68 | AU5: 68 | AV5: 56 | AW5: 68
A6: 4 | B6: 2695 | C6: 281 | D6: 116 | E6: 116 | F6: 76 | G6: 32 | H6: 2780 | I6: 244 | J6: 160 | K6: 57 | L6: 76 | M6: 32 | N6: 3140 | O6: 345 | P6: 78 | Q6: 78 | R6: 125 | S6: 32 | T6: 1157 | U6: 234 | V6: 160 | W6: 160 | X6: 54 | Y6: 32 | Z6: 2180 | AA6: 245 | AB6: 116 | AC6: 174 | AD6: 76 | AE6: 32 | AF6: 3040 | AG6: 306 | AH6: 91 | AI6: 91 | AJ6: 73 | AK6: 54 | AL6: 1900 | AM6: 252 | AN6: 91 | AO6: 91 | AP6: 54 | AQ6: 32 | AR6: 1900 | AS6: 271 | AT6: 91 | AU6: 91 | AV6: 73 | AW6: 89
A7: 5 | B7: 9240 | C7: 300 | D7: 146 | E7: 146 | F7: 94 | G7: 38 | H7: 11850 | I7: 258 | J7: 200 | K7: 70 | L7: 94 | M7: 38 | N7: 13260 | O7: 378 | P7: 98 | Q7: 98 | R7: 155 | S7: 38 | T7: 5550 | U7: 244 | V7: 200 | W7: 200 | X7: 66 | Y7: 38 | Z7: 9030 | AA7: 264 | AB7: 146 | AC7: 219 | AD7: 94 | AE7: 38 | AF7: 11280 | AG7: 332 | AH7: 114 | AI7: 114 | AJ7: 90 | AK7: 66 | AL7: 7800 | AM7: 262 | AN7: 114 | AO7: 114 | AP7: 66 | AQ7: 38 | AR7: 7800 | AS7: 286 | AT7: 114 | AU7: 114 | AV7: 90 | AW7: 110
A8: 6 | B8: 11790 | C8: 310 | D8: 204 | E8: 204 | F8: 119 | G8: 43 | H8: 13775 | I8: 274 | J8: 280 | K8: 98 | L8: 89 | M8: 43 | N8: 16310 | O8: 388 | P8: 137 | Q8: 137 | R8: 154 | S8: 43 | T8: 7075 | U8: 239 | V8: 280 | W8: 280 | X8: 74 | Y8: 43 | Z8: 11145 | AA8: 267 | AB8: 146 | AC8: 300 | AD8: 94 | AE8: 43 | AF8: 13400 | AG8: 275 | AH8: 160 | AI8: 160 | AJ8: 89 | AK8: 68 | AL8: 9750 | AM8: 283 | AN8: 160 | AO8: 160 | AP8: 84 | AQ8: 43 | AR8: 9740 | AS8: 303 | AT8: 160 | AU8: 160 | AV8: 117 | AW8: 110
A9: 7 | B9: 16440 | C9: 320 | D9: 294 | E9: 294 | F9: 159 | G9: 48 | H9: 19400 | I9: 279 | J9: 400 | K9: 128 | L9: 129 | M9: 48 | N9: 22910 | O9: 398 | P9: 167 | Q9: 167 | R9: 194 | S9: 48 | T9: 9700 | U9: 244 | V9: 400 | W9: 400 | X9: 114 | Y9: 48 | Z9: 15720 | AA9: 272 | AB9: 176 | AC9: 420 | AD9: 134 | AE9: 48 | AF9: 19400 | AG9: 285 | AH9: 220 | AI9: 220 | AJ9: 129 | AK9: 78 | AL9: 13500 | AM9: 288 | AN9: 220 | AO9: 220 | AP9: 124 | AQ9: 48 | AR9: 13640 | AS9: 308 | AT9: 220 | AU9: 220 | AV9: 197 | AW9: 120
A10: 8 | B10: 21090 | C10: 330 | D10: 384 | E10: 384 | F10: 199 | G10: 53 | H10: 25025 | I10: 284 | J10: 520 | K10: 158 | L10: 169 | M10: 53 | N10: 29510 | O10: 408 | P10: 197 | Q10: 197 | R10: 234 | S10: 53 | T10: 12325 | U10: 249 | V10: 520 | W10: 520 | X10: 154 | Y10: 53 | Z10: 20295 | AA10: 282 | AB10: 206 | AC10: 540 | AD10: 174 | AE10: 53 | AF10: 25400 | AG10: 295 | AH10: 280 | AI10: 280 | AJ10: 169 | AK10: 88 | AL10: 17250 | AM10: 293 | AN10: 280 | AO10: 280 | AP10: 164 | AQ10: 53 | AR10: 17540 | AS10: 313 | AT10: 280 | AU10: 280 | AV10: 277 | AW10: 130

Sheet Weapons
A1: Name | B1: Type | C1: Faction | D1: Hands | E1: RAGE | F1: GUARD POWER | G1: STAMINA | H1: REQ | I1: RAW TYPE | J1: RAW % | K1: E TYPE | L1: E % | M1: STR % | N1: DEX % | O1: T1 | P1: T2 | Q1: T3 | R1: T4 | S1: 9 | T1: 14 | U1: 19 | V1: HEADSHOT
A2: Beam Katana | B2: Katana | C2: DOD | D2: 1-Handed | E2: 1 | F2: B | G2: B | H2: STR | I2: Slash | J2: 050 | K2: Electric | L2: 050 | M2: 090 | N2: 010 | O2: 42 | P2: 108 | Q2: 640 | R2: 3501 | S2: 4052 | T2: 4698 | U2: 5446
A3: Buzzsaw | B3: Buzzsaw | C3: DOD | D3: 1-Handed | E3: 1 | F3: C | G3: A | H3: LUK | I3: Slash | J3: 100 | M3: 080 | N3: 020 | O3: 38 | P3: 97 | Q3: 576 | R3: 1975 | S3: 2287 | T3: 2651 | U3: 3073
A4: Hammer | B4: Hammer | C4: DOD | D4: 1-Handed | E4: 2 | F4: C | G4: B | H4: STM | I4: Blunt | J4: 100 | M4: 100 | N4: 000 | O4: 31 | P4: 79 | Q4: 467 | R4: 1854 | S4: 2147 | T4: 2489 | U4: 2886
A5: Pickaxe | B5: Pickaxe | C5: DOD | D5: 2-Handed | E5: 1 | F5: B | G5: C | H5: STM | I5: Slash | J5: 100 | M5: 100 | N5: 000 | O5: 40 | P5: 104 | Q5: 617 | R5: 3219 | S5: 3727 | T5: 4321 | U5: 5009
A6: Nail Gun | B6: Nail Gun | C6: DOD | D6: 1-Handed | E6: 2 | F6: C | G6: - | H6: VIT | I6: Piercing | J6: 100 | M6: 000 | N6: 100 | O6: 53 | P6: 136 | Q6: 373 | R6: 1736 | S6: 2011 | T6: 2331 | U6: 2702
A7: Welding Gun | B7: Welding Gun | C7: DOD | D7: 1-Handed | E7: 1 | F7: C | G7: - | H7: VIT | I7: Piercing | J7: 050 | K7: Fire | L7: 050 | M7: 010 | N7: 090 | O7: 146 | P7: 420 | Q7: 475 | R7: 2294 | S7: 2656 | T7: 3079 | U7: 3569
A8: Drill | B8: Drill | C8: DOD | D8: 1-Handed | E8: 1 | F8: B | G8: D | H8: HP | I8: Slash | J8: 100 | M8: 100 | N8: 000 | O8: 470 | P8: 870 | Q8: 1098 | R8: 2248 | S8: 2603 | T8: 3017 | U8: 3498
A9: Iron | B9: Iron | C9: DOD | D9: 1-Handed | E9: 1 | F9: C | G9: - | H9: LUK | I9: Blunt | J9: 050 | K9: Fire | L9: 050 | M9: 100 | N9: 000 | O9: 42 | P9: 107 | Q9: 711 | R9: 1521 | S9: 1761 | T9: 2041 | U9: 2367
A10: Chopper | B10: Chopper | C10: DOD | D10: 1-Handed | E10: 1 | F10: C | G10: B | H10: STR | I10: Slash | J10: 100 | M10: 090 | N10: 010 | O10: 635 | P10: 1174 | Q10: 1482 | R10: 3752 | S10: 4343 | T10: 5035 | U10: 5837
A11: Fireworks | B11: Fireworks | C11: DOD | D11: 1-Handed | E11: 2 | F11: C | G11: - | H11: HP | I11: Piercing | J11: 010 | K11: Fire | L11: 090 | M11: 000 | N11: 100 | O11: 28 | P11: 71 | Q11: 425 | R11: 2877 | S11: 3330 | T11: 3860 | U11: 4475
A12: Chainsaw | B12: Chainsaw | C12: DOD | D12: 2-Handed | E12: 3 | F12: B | G12: C | H12: HP | I12: Slash | J12: 100 | M12: 100 | N12: 000 | O12: 77 | P12: 244 | Q12: 804 | R12: 1072 | S12: 1241 | T12: 1439 | U12: 1668
A13: Spike Crusher | B13: Spike Crusher | C13: DOD | D13: 1-Handed | E13: 3 | F13: B | G13: C | H13: STR | I13: Blunt | J13: 100 | M13: 100 | N13: 000 | R13: 2377 | S13: 2572 | T13: 2703 | U13: 2841
A14: Hell Spike Crusher | B14: Spike Crusher | C14: DOD | D14: 1-Handed | E14: 3 | F14: B | G14: C | H14: STR | I14: Blunt | J14: 040 | K14: Poison | L14: 060 | M14: 100 | N14: 000 | R14: 3556
A15: Static Massager | B15: Static Massager | C15: DOD | D15: 1-Handed | E15: 2 | F15: C | G15: - | H15: DEX | I15: Piercing | J15: 010 | K15: Electric | L15: 090 | M15: 040 | N15: 060 | R15: 2824 | S15: 3056 | T15: 3212 | U15: 3376
A16: Viral Massager | B16: Static Massager | C16: DOD | D16: 1-Handed | E16: 2 | F16: C | G16: - | H16: DEX | I16: Piercing | J16: 010 | K16: Poison | L16: 090 | M16: 040 | N16: 060 | R16: 3760
A17: Timber | B17: Timber | C17: DOD | D17: 2-Handed | E17: 3 | F17: B | G17: - | H17: HP | I17: Blunt | J17: 100 | M17: 100 | N17: 000 | O17: 450 | P17: 1242 | Q17: 1628 | R17: 3080 | S17: 3564 | T17: 4132 | U17: 4790
A18: Machete | B18: Machete | C18: WA | D18: 1-Handed | E18: 1 | F18: B | G18: B | H18: STR | I18: Slash | J18: 050 | K18: Fire | L18: 050 | M18: 090 | N18: 010 | O18: 32 | P18: 83 | Q18: 492 | R18: 2693 | S18: 3117 | T18: 3614 | U18: 4189
A19: Knife | B19: Knife | C19: WA | D19: 1-Handed | E19: 1 | F19: C | G19: A | H19: DEX | I19: Slash | J19: 100 | M19: 090 | N19: 010 | O19: 71 | P19: 184 | Q19: 453 | R19: 2790 | S19: 3230 | T19: 3744 | U19: 4341
A20: Flamethrower | B20: Flamethrower | C20: WA | D20: 1-Handed | E20: 2 | F20: C | G20: - | H20: STM | I20: Piercing | J20: 020 | K20: Fire | L20: 080 | M20: 000 | N20: 100 | O20: 266 | P20: 763 | Q20: 863 | R20: 3561 | S20: 4122 | T20: 4779 | U20: 5540
A21: Magnum | B21: Magnum | C21: WA | D21: 2-Handed | E21: 2 | F21: C | G21: - | H21: DEX | I21: Piercing | J21: 100 | M21: 030 | N21: 070 | O21: 42 | P21: 107 | Q21: 634 | R21: 3066 | S21: 3549 | T21: 4115 | U21: 4770 | V21: 2.38
A22: Demon Gun | B22: Magnum | C22: WA | D22: 2-Handed | E22: 2 | F22: C | G22: - | H22: DEX | I22: Piercing | J22: 100 | M22: 030 | N22: 070 | O22: 42 | P22: 107 | Q22: 634 | R22: 3066 | S22: 3549 | T22: 4115 | U22: 4770
A23: Stun Rod | B23: Stun Rod | C23: WA | D23: 1-Handed | E23: 3 | F23: C | G23: B | H23: VIT | I23: Blunt | J23: 050 | K23: Electric | L23: 050 | M23: 020 | N23: 080 | O23: 108 | P23: 278 | Q23: 764 | R23: 1966 | S23: 2276 | T23: 2639 | U23: 3059
A24: Shotgun | B24: Shotgun | C24: WA | D24: 1-Handed | E24: 1 | F24: C | G24: - | H24: STM | I24: Piercing | J24: 100 | M24: 020 | N24: 080 | O24: 59 | P24: 153 | Q24: 422 | R24: 2235 | S24: 2587 | T24: 2999 | U24: 3477
A25: Sniper Rifle | B25: Sniper Rifle | C25: WA | D25: 2-Handed | E25: 3 | F25: C | G25: - | H25: LUK | I25: Piercing | J25: 100 | M25: 020 | N25: 080 | O25: 131 | P25: 338 | Q25: 928 | R25: 1999 | S25: 2315 | T25: 2683 | U25: 3111 | V25: 2.5
A26: GLIDER | B26: GLIDER | C26: WA | D26: 2-Handed | E26: 3 | F26: C | G26: - | H26: LUK | I26: Piercing | J26: 100 | M26: 020 | N26: 080 | O26: 136 | P26: 349 | Q26: 956 | R26: 2060 | S26: 2384 | T26: 2764 | U26: 3205
A27: Assault Rifle | B27: Assault Rifle | C27: WA | D27: 2-Handed | E27: 1 | F27: C | G27: - | H27: DEX | I27: Piercing | J27: 100 | M27: 000 | N27: 100 | O27: 62 | P27: 159 | Q27: 391 | R27: 2394 | S27: 2772 | T27: 3213 | U27: 3725 | V27: 1.5
A28: Assault Rifle WoT | B28: Assault Rifle | C28: WA | D28: 2-Handed | E28: 1 | F28: C | G28: - | H28: DEX | I28: Piercing | J28: 100 | M28: 000 | N28: 100 | O28: 64 | P28: 159 | Q28: 391 | R28: 2394 | S28: 2772 | T28: 3213 | U28: 3725 | V28: 1.5
A29: Assault Rifle RE | B29: Assault Rifle | C29: WA | D29: 2-Handed | E29: 1 | F29: C | G29: - | H29: DEX | I29: Piercing | J29: 100 | M29: 000 | N29: 100 | O29: 71 | P29: 183 | Q29: 449 | R29: 2754 | S29: 3187 | T29: 3695 | U29: 4283 | V29: 1.5
A30: Shovel | B30: Shovel | C30: WA | D30: 1-Handed | E30: 3 | F30: B | G30: D | H30: STM | I30: Slash | J30: 100 | M30: 100 | N30: 000 | O30: 734 | P30: 2100 | Q30: 2654 | R30: 5934 | S30: 7214 | T30: 8363 | U30: 9695
A31: Rocket Launcher | B31: Rocket Launcher | C31: WA | D31: 2-Handed | E31: 1 | F31: C | G31: - | H31: HP | I31: Piercing | J31: 080 | K31: Fire | L31: 020 | M31: 000 | N31: 100 | O31: 1118 | P31: 2625 | Q31: 3311 | R31: 6009 | S31: 6955 | T31: 8063 | U31: 9347
A32: M2G-87 | B32: M2G-87 | C32: WA | D32: 2-Handed | E32: 3 | F32: C | G32: - | H32: DEX | I32: Piercing | J32: 100 | M32: 070 | N32: 030 | R32: 3303 | S32: 3574 | T32: 3756 | U32: 3948 | V32: 2.55
A33: M2G-87 Mod.1 FireFly | B33: M2G-87 | C33: WA | D33: 2-Handed | E33: 3 | F33: C | G33: - | H33: DEX | I33: Piercing | J33: 70 | K33: Fire | L33: 30 | M33: 070 | N33: 030 | R33: 4208 | V33: 2.55
A34: Stun Gun | B34: Stun Gun | C34: WA | D34: 1-Handed | E34: 2 | F34: C | G34: - | H34: LUK | I34: Piercing | J34: 001 | K34: Electric | L34: 099 | M34: 000 | N34: 100 | O34: 141 | P34: 405 | Q34: 512 | R34: 1914 | S34: 2216 | T34: 2569 | U34: 2978
A35: Axe | B35: Axe | C35: CW | D35: 2-Handed | E35: 2 | F35: A | G35: D | H35: STR | I35: Slash | J35: 100 | M35: 100 | N35: 000 | O35: 131 | P35: 338 | Q35: 928 | R35: 3693 | S35: 4275 | T35: 4956 | U35: 5746
A36: Crossbow | B36: Crossbow | C36: CW | D36: 1-Handed | E36: 2 | F36: C | G36: - | H36: DEX | I36: Piercing | J36: 100 | M36: 000 | N36: 100 | O36: 21 | P36: 53 | Q36: 317 | R36: 1469 | S36: 1701 | T36: 1972 | U36: 2287
A37: Spear | B37: Spear | C37: CW | D37: 2-Handed | E37: 2 | F37: B | G37: C | H37: STM | I37: Slash | J37: 100 | M37: 100 | N37: 000 | O37: 310 | P37: 887 | Q37: 1120 | R37: 4272 | S37: 4945 | T37: 5733 | U37: 6646
A38: Katana | B38: Katana | C38: CW | D38: 2-Handed | E38: 3 | F38: B | G38: C | H38: DEX | I38: Slash | J38: 100 | M38: 060 | N38: 040 | O38: 659 | P38: 1217 | Q38: 1536 | R38: 2940 | S38: 3403 | T38: 3945 | U38: 4574
A39: Sword | B39: Sword | C39: CW | D39: 1-Handed | E39: 2 | F39: B | G39: B | H39: STR | I39: Slash | J39: 050 | K39: Fire | L39: 050 | M39: 090 | N39: 010 | O39: 97 | P39: 175 | Q39: 800 | R39: 2489 | S39: 2881 | T39: 3340 | U39: 3872
A40: Sword RE | B40: Sword | C40: CW | D40: 1-Handed | E40: 2 | F40: B | G40: B | H40: STR | I40: Slash | J40: 050 | K40: Fire | L40: 050 | M40: 090 | N40: 010 | O40: 112 | P40: 202 | Q40: 921 | R40: 2863 | S40: 3313 | T40: 3841 | U40: 4453
...

Sheet Lists
A1: FIGHTER CLASSES | C1: WEAPON TYPES | E1: RAW TYPE | G1: ELEMENT TYPE | I1: LUK | J1: Crit Chance
A2: All-rounder | C2: Archer's Bow | E2: Slash | G2: None | I2: 10 | J2: 6.8
A3: Striker | C3: Assault Rifle | E3: Blunt | G3: Fire | I3: 11 | J3: 8.4
A4: Defender | C4: Axe | E4: Piercing | G4: Electric | I4: 12 | J4: 9.9
A5: Attacker | C5: Bat | G5: Poison | I5: 13 | J5: 11.3
A6: Shooter | C6: Bowling Ball | I6: 14 | J6: 12.6
A7: Collector | C7: Boxing Gloves | I7: 15 | J7: 13.8
A8: Skill Master | C8: Buzzsaw | I8: 16 | J8: 14.9
A9: Lucky Star | C9: Chainsaw | I9: 17 | J9: 15.9
C10: Chopper | I10: 18 | J10: 16.9
C11: Claw | I11: 19 | J11: 17.8
C12: Crossbow | I12: 20 | J12: 18.7
C13: Drill | I13: 21 | J13: 19.6
C14: Fire Baton | I14: 22 | J14: 20.4
C15: Fire Rod | I15: 23 | J15: 21.1
C16: Fireworks | I16: 24 | J16: 21.9
C17: Flail | I17: 25 | J17: 22.6
C18: Flamethrower | I18: 26 | J18: 23.2
C19: Hammer | I19: 27 | J19: 23.9
C20: Hockey Stick | I20: 28 | J20: 24.5
C21: Iron | I21: 29 | J21: 25.1
... C45: Yo-Yo | I45: 53 | J45: 35.5
I46: 54 | J46: 35.8
I47: 55 | J47: 36.1
I48: 56 | J48: 36.4
I49: 57 | J49: 36.7
I50: 58 | J50: 37
I51: 59 | J51: 37.3
I52: 60 | J52: 37.6
I53: 61 | J53: 37.9
I54: 62 | J54: 38.2
I55: 63 | J55: 38.5
I56: 64 | J56: 38.7
I57: 65 | J57: 39
... I192: 200 | J192: 50

Sheet Notes
A1: Attack Damage Formula | C1: (Current working formula. Will be changed as better information is gathered)
A3: ATK * FUN * Scale * Coeff * (1-RES)
A6: Defense Formula
A8: 1.1 +((DEF * FUN * (VIT + 25)) / 23200)
A11: Final Damage Calculation
A13: ATK FORM / DEF FORM
