Workbook
Name Arms_List: Arms!$A$1:$A$542
Name Bodies_List: Bodies!$A$1:$A$542
Name Gunlance_List: Gunlance!$A$19:$A$394
Name Helmets_List: Helmets!$A$1:$A$542
Name Legs_List: Legs!$A$1:$A$542
Name Waists_List: Waists!$A$1:$A$542

Sheet Build
A1: WEAPON TYPE | D1: Gunlance | H1: EQUIPMENT SKILLS | O1: ALL SKILLS
A2: MONSTER | D2: DEVILJHO | H2: WEAPON | I2: {=_xlfn.LET( _xlpm.ind,INDEX( INDIRECT("'" & $D$1 & "'!A1:BA500"), MATCH($D$2, INDIRECT($D$1 & "_List"), 0) +4, MATCH($D$3, INDIRECT("'" & $D$1 & "'!A1:BA1"), 0) ), IF(_xlpm.ind<>0, _xlpm.ind, "") )} -> Defense Boost | L2: {=_xlfn.LET( _xlpm.ind,INDEX( INDIRECT("'" & $D$1 & "'!A1:BA500"), MATCH($D$2, INDIRECT($D$1 & "_List"), 0) + 4, MATCH($D$3, INDIRECT("'" & $D$1 & "'!A1:BA1"), 0) + 2 ), IF(_xlpm.ind<>0, _xlpm.ind, "") )} -> 2 | O2: {=_xlfn.LET( _xlpm.range, _xlfn.VSTACK(I2:I4,I7:I11,I14:I18,I21:I25,I28:I32,I35:I39), _xlpm.fr, _xlfn._xlws.FILTER(_xlpm.range, _xlpm.range<>0), _xlfn.UNIQUE(_xlfn._xlws.FILTER(_xlpm.fr,_xlpm.fr<>"","")) )} -> Defense Boost | R2: =_xlfn.LET( _xlpm.c, SUMIF($I$2:$I$39,O2,$L$2:$L$39), IF(_xlpm.c<>0, _xlpm.c, "") ) -> 2
A3: GRADE | D3: GRADE 10 | I3: {=_xlfn.LET( _xlpm.ind,INDEX( INDIRECT("'" & $D$1 & "'!A1:BA500"), MATCH($D$2, INDIRECT($D$1 & "_List"), 0) + 5, MATCH($D$3, INDIRECT("'" & $D$1 & "'!A1:BA1"), 0) ), IF(_xlpm.ind<>0, _xlpm.ind, "") )} | L3: {=_xlfn.LET( _xlpm.ind,INDEX( INDIRECT("'" & $D$1 & "'!A1:BA500"), MATCH($D$2, INDIRECT($D$1 & "_List"), 0) + 5, MATCH($D$3, INDIRECT("'" & $D$1 & "'!A1:BA1"), 0) + 2 ), IF(_xlpm.ind<>0, _xlpm.ind, "") )} | O3: Advanced Attack Boost | R3: =_xlfn.LET( _xlpm.c, SUMIF($I$2:$I$39,O3,$L$2:$L$39), IF(_xlpm.c<>0, _xlpm.c, "") ) -> 1
I4: {=_xlfn.LET( _xlpm.ind,INDEX( INDIRECT("'" & $D$1 & "'!A1:BA500"), MATCH($D$2, INDIRECT($D$1 & "_List"), 0) + 5, MATCH($D$3, INDIRECT("'" & $D$1 & "'!A1:BA1"), 0) ), IF(_xlpm.ind<>0, _xlpm.ind, "") )} | L4: {=_xlfn.LET( _xlpm.ind,INDEX( INDIRECT("'" & $D$1 & "'!A1:BA500"), MATCH($D$2, INDIRECT($D$1 & "_List"), 0) + 6, MATCH($D$3, INDIRECT("'" & $D$1 & "'!A1:BA1"), 0) + 2 ), IF(_xlpm.ind<>0, _xlpm.ind, "") )} | O4: Reckless | R4: =_xlfn.LET( _xlpm.c, SUMIF($I$2:$I$39,O4,$L$2:$L$39), IF(_xlpm.c<>0, _xlpm.c, "") ) -> 2
A5: ORIGINAL | R5: =_xlfn.LET( _xlpm.c, SUMIF($I$2:$I$39,O5,$L$2:$L$39), IF(_xlpm.c<>0, _xlpm.c, "") )
A6: ATK | C6: {=INDEX( INDIRECT("'" & $D$1 & "'!A1:BA500"), MATCH($D$2, INDIRECT($D$1 & "_List"), 0) + 1, MATCH($D$3, INDIRECT("'" & $D$1 & "'!A1:BA1"), 0) )} -> 2103 | H6: HEAD | I6: BRUTE TIGREX | L6: GRADE 8 | R6: =_xlfn.LET( _xlpm.c, SUMIF($I$2:$I$39,O6,$L$2:$L$39), IF(_xlpm.c<>0, _xlpm.c, "") )
A7: ELE | C7: {=INDEX( INDIRECT("'" & $D$1 & "'!A1:BA500"), MATCH($D$2, INDIRECT($D$1 & "_List"), 0) + 2, MATCH($D$3, INDIRECT("'" & $D$1 & "'!A1:BA1"), 0) )} -> 0 | E7: {=INDEX( INDIRECT("'" & $D$1 & "'!A1:AZ200"), MATCH($D$2, INDIRECT($D$1 & "_List"), 0) + 1, 3 )} -> ATK | I7: {=INDEX(Helmets!A1:BA500, MATCH(I6, Helmets_List, 0) + 3, MATCH(Build!L6,Helmets!A1:AG1,0) )} -> Advanced Attack Boost | L7: {=INDEX(Helmets!A1:BA500, MATCH(I6, Helmets_List, 0) + 3, MATCH(Build!L6,Helmets!A1:AG1,0) + 2 )} -> 1 | R7: =_xlfn.LET( _xlpm.c, SUMIF($I$2:$I$39,O7,$L$2:$L$39), IF(_xlpm.c<>0, _xlpm.c, "") )
A8: SHELL TYPE | C8: =IF(D1="Gunlance", INDEX( INDIRECT("'" & $D$1 & "'!A1:BA500"), MATCH($D$2, INDIRECT($D$1 & "_List"), 0), 3 ), "NONE" ) -> WIDE | I8: {=INDEX(Helmets!A1:BA500, MATCH(I6, Helmets_List, 0) + 4, MATCH(Build!L6,Helmets!A1:AG1,0) )} -> Reckless | L8: {=INDEX(Helmets!A1:BA500, MATCH(I6, Helmets_List, 0) + 4, MATCH(Build!L6,Helmets!A1:AG1,0) + 2 )} -> 2 | R8: =_xlfn.LET( _xlpm.c, SUMIF($I$2:$I$39,O8,$L$2:$L$39), IF(_xlpm.c<>0, _xlpm.c, "") )
A9: SHELL COUNT | C9: =IF(D1="Gunlance", _xlfn.XLOOKUP(C8,Lists!T3:T5,Lists!U3:U5), 0) -> 2 | I9: {=INDEX(Helmets!A1:BA500, MATCH(I6, Helmets_List, 0) + 5, MATCH(Build!L6,Helmets!A1:AG1,0) )} -> 0 | L9: {=INDEX(Helmets!A1:BA500, MATCH(I6, Helmets_List, 0) + 5, MATCH(Build!L6,Helmets!A1:AG1,0) + 2 )} -> 0 | R9: =_xlfn.LET( _xlpm.c, SUMIF($I$2:$I$39,O9,$L$2:$L$39), IF(_xlpm.c<>0, _xlpm.c, "") )
A10: SHELL | C10: =IF(D1="Gunlance", INDEX(Lists!I4:R6, MATCH(Build!C8,Lists!H4:H6,0), MATCH(Build!D3,Lists!I2:R2, 0) ), 0 ) -> 1309 | H10: DRIFTS | L10: =IF(I10<>"", 1, "") | R10: =_xlfn.LET( _xlpm.c, SUMIF($I$2:$I$39,O10,$L$2:$L$39), IF(_xlpm.c<>0, _xlpm.c, "") )
A11: CHARGED SHELL | C11: =IF(D1="Gunlance", INDEX(Lists!I8:R10, MATCH(Build!C8,Lists!H8:H10,0), MATCH(Build!D3,Lists!I2:R2, 0) ), 0 ) -> 1820 | L11: =IF(I11<>"", 1, "") | R11: =_xlfn.LET( _xlpm.c, SUMIF($I$2:$I$39,O11,$L$2:$L$39), IF(_xlpm.c<>0, _xlpm.c, "") )
A12: BURST SHELL | C12: =IF(D1="Gunlance", INDEX(Lists!I12:R14, MATCH(Build!C8,Lists!H12:H14,0), MATCH(Build!D3,Lists!I2:R2, 0) ), 0 ) -> 1150 | R12: =_xlfn.LET( _xlpm.c, SUMIF($I$2:$I$39,O12,$L$2:$L$39), IF(_xlpm.c<>0, _xlpm.c, "") )
A13: FULL BURST | C13: =IF(D1="Gunlance", C9 * C12, 0) -> 2300 | H13: BODY | I13: KULU-YA-KU | L13: GRADE 5 | R13: =_xlfn.LET( _xlpm.c, SUMIF($I$2:$I$39,O13,$L$2:$L$39), IF(_xlpm.c<>0, _xlpm.c, "") )
R14: =_xlfn.LET( _xlpm.c, SUMIF($I$2:$I$39,O14,$L$2:$L$39), IF(_xlpm.c<>0, _xlpm.c, "") )
A15: AFTER SKILLS | R15: =_xlfn.LET( _xlpm.c, SUMIF($I$2:$I$39,O15,$L$2:$L$39), IF(_xlpm.c<>0, _xlpm.c, "") )
A16: ATK | C16: =C6 + Skills!P2 * (Skills!R2 / 100 + 1) -> 2253 | R16: =_xlfn.LET( _xlpm.c, SUMIF($I$2:$I$39,O16,$L$2:$L$39), IF(_xlpm.c<>0, _xlpm.c, "") )
A17: ELE | C17: =C7 + SUMIF(Skills!N5:O18,Build!E17,Skills!P5:Q18) * (SUMIF(Skills!N5:O18,Build!E17,Skills!R5:S18) / 100 + 1) -> 0 | E17: =E7 -> ATK | H17: DRIFTS | L17: =IF(I17<>"", 1, "") | R17: =_xlfn.LET( _xlpm.c, SUMIF($I$2:$I$39,O17,$L$2:$L$39), IF(_xlpm.c<>0, _xlpm.c, "") )
A18: SHELL TYPE | C18: =C8 -> WIDE | L18: =IF(I18<>"", 1, "") | R18: =_xlfn.LET( _xlpm.c, SUMIF($I$2:$I$39,O18,$L$2:$L$39), IF(_xlpm.c<>0, _xlpm.c, "") )
A19: SHELL COUNT | C19: =C9 + IF(Skills!K4>=3, 1,0) -> 2 | R19: =_xlfn.LET( _xlpm.c, SUMIF($I$2:$I$39,O19,$L$2:$L$39), IF(_xlpm.c<>0, _xlpm.c, "") )
A20: SHELL | C20: =C10 * (Skills!R4 / 100 + 1) * (Skills!R3 / 100 + 1) -> 1439.9 | H20: ARMS | R20: =_xlfn.LET( _xlpm.c, SUMIF($I$2:$I$39,O20,$L$2:$L$39), IF(_xlpm.c<>0, _xlpm.c, "") )
A21: CHARGED SHELL | C21: =C11 * (Skills!R4 / 100 + 1) * (Skills!R3 / 100 + 1) -> 2002 | R21: =_xlfn.LET( _xlpm.c, SUMIF($I$2:$I$39,O21,$L$2:$L$39), IF(_xlpm.c<>0, _xlpm.c, "") )
A22: BURST SHELL | C22: =C12 * (Skills!R4 / 100 + 1) * (Skills!R3 / 100 + 1) -> 1265 | R22: =_xlfn.LET( _xlpm.c, SUMIF($I$2:$I$39,O22,$L$2:$L$39), IF(_xlpm.c<>0, _xlpm.c, "") )
A23: FULL BURST | C23: =IF(D1="Gunlance", C19 * C22, 0) -> 2530 | R23: =_xlfn.LET( _xlpm.c, SUMIF($I$2:$I$39,O23,$L$2:$L$39), IF(_xlpm.c<>0, _xlpm.c, "") )
H24: DRIFTS | L24: =IF(I24<>"", 1, "") | R24: =_xlfn.LET( _xlpm.c, SUMIF($I$2:$I$39,O24,$L$2:$L$39), IF(_xlpm.c<>0, _xlpm.c, "") )
L25: =IF(I25<>"", 1, "") | R25: =_xlfn.LET( _xlpm.c, SUMIF($I$2:$I$39,O25,$L$2:$L$39), IF(_xlpm.c<>0, _xlpm.c, "") )
H27: WAIST
H31: DRIFTS | L31: =IF(I31<>"", 1, "")
L32: =IF(I32<>"", 1, "")
H34: LEGS
H38: DRIFTS | L38: =IF(I38<>"", 1, "")
L39: =IF(I39<>"", 1, "")

Sheet Skills
A1: NAME | B1: LEVELS | C1: TYPE | D1: CONDITIONAL | E1: BUFF TYPE | F1: L1 | G1: L2 | H1: L3 | I1: L4 | J1: L5 | K1: IN BUILD | L1: APPLIED VALUE | N1: DMG BOOST TYPES | P1: TOTAL FLAT | R1: TOTAL %
A2: Attack Boost | B2: 5 | C2: ATK | D2: NO | E2: FLAT | F2: 50 | G2: 100 | H2: 150 | I2: 200 | J2: 300 | K2: =SUMIF(Build!$O$2:$O$25, Table1[[#This Row],[NAME]],Build!$R$2:$R$25) -> 0 | L2: {=_xlfn.LET( _xlpm.val, IF(Table1[[#This Row],[IN BUILD]]>Table1[[#This Row],[LEVELS]],Table1[[#This Row],[LEVELS]],Table1[[#This Row],[IN BUILD]]), IF(_xlpm.val = 0,0, INDIRECT(ADDRESS(ROW(), 6 + (_xlpm.val -1)))) )} -> 0 | N2: ATK | P2: =SUMIFS(Table1[APPLIED VALUE],Table1[BUFF TYPE],"FLAT",Table1[TYPE],N2) -> 150 | R2: =SUMIFS(Table1[APPLIED VALUE],Table1[BUFF TYPE],"%",Table1[TYPE],N2) -> 0
A3: Advanced Attack Boost | B3: 2 | C3: ATK | D3: NO | E3: FLAT | F3: 150 | G3: 350 | H3: 0 | I3: 0 | J3: 0 | K3: =SUMIF(Build!$O$2:$O$25, Table1[[#This Row],[NAME]],Build!$R$2:$R$25) -> 1 | L3: {=_xlfn.LET( _xlpm.val, IF(Table1[[#This Row],[IN BUILD]]>Table1[[#This Row],[LEVELS]],Table1[[#This Row],[LEVELS]],Table1[[#This Row],[IN BUILD]]), IF(_xlpm.val = 0,0, INDIRECT(ADDRESS(ROW(), 6 + (_xlpm.val -1)))) )} -> 150 | N3: DMG | P3: =SUMIFS(Table1[APPLIED VALUE],Table1[BUFF TYPE],"FLAT",Table1[TYPE],N3) -> 0 | R3: =SUMIFS(Table1[APPLIED VALUE],Table1[BUFF TYPE],"%",Table1[TYPE],N3) -> 10
A4: Artillery | B4: 5 | C4: SHELL | D4: NO | E4: % | F4: 10 | G4: 15 | H4: 20 | I4: 30 | J4: 40 | K4: =SUMIF(Build!$O$2:$O$25, Table1[[#This Row],[NAME]],Build!$R$2:$R$25) -> 0 | L4: {=_xlfn.LET( _xlpm.val, IF(Table1[[#This Row],[IN BUILD]]>Table1[[#This Row],[LEVELS]],Table1[[#This Row],[LEVELS]],Table1[[#This Row],[IN BUILD]]), IF(_xlpm.val = 0,0, INDIRECT(ADDRESS(ROW(), 6 + (_xlpm.val -1)))) )} -> 0 | N4: SHELL | P4: =SUMIFS(Table1[APPLIED VALUE],Table1[BUFF TYPE],"FLAT",Table1[TYPE],N4) -> 0 | R4: =SUMIFS(Table1[APPLIED VALUE],Table1[BUFF TYPE],"%",Table1[TYPE],N4) -> 0
A5: Reckless | B5: 3 | C5: DMG | D5: NO | E5: % | F5: 5 | G5: 10 | H5: 20 | I5: 0 | J5: 0 | K5: =SUMIF(Build!$O$2:$O$25, Table1[[#This Row],[NAME]],Build!$R$2:$R$25) -> 2 | L5: {=_xlfn.LET( _xlpm.val, IF(Table1[[#This Row],[IN BUILD]]>Table1[[#This Row],[LEVELS]],Table1[[#This Row],[LEVELS]],Table1[[#This Row],[IN BUILD]]), IF(_xlpm.val = 0,0, INDIRECT(ADDRESS(ROW(), 6 + (_xlpm.val -1)))) )} -> 10 | N5: FIRE | P5: =SUMIFS(Table1[APPLIED VALUE],Table1[BUFF TYPE],"FLAT",Table1[TYPE],N5) -> 0 | R5: =SUMIFS(Table1[APPLIED VALUE],Table1[BUFF TYPE],"%",Table1[TYPE],N5) -> 0
A6: Nergigante Avidity | B6: 3 | C6: DMG | D6: NO | E6: % | F6: 10 | G6: 15 | H6: 20 | I6: 0 | J6: 0 | K6: =SUMIF(Build!$O$2:$O$25, Table1[[#This Row],[NAME]],Build!$R$2:$R$25) -> 0 | L6: {=_xlfn.LET( _xlpm.val, IF(Table1[[#This Row],[IN BUILD]]>Table1[[#This Row],[LEVELS]],Table1[[#This Row],[LEVELS]],Table1[[#This Row],[IN BUILD]]), IF(_xlpm.val = 0,0, INDIRECT(ADDRESS(ROW(), 6 + (_xlpm.val -1)))) )} -> 0 | N6: WATER | P6: =SUMIFS(Table1[APPLIED VALUE],Table1[BUFF TYPE],"FLAT",Table1[TYPE],N6) -> 0 | R6: =SUMIFS(Table1[APPLIED VALUE],Table1[BUFF TYPE],"%",Table1[TYPE],N6) -> 0
A7: Offensive Guard | B7: 5 | C7: ATK | D7: YES | E7: % | F7: 10 | G7: 15 | H7: 20 | I7: 30 | J7: 40 | K7: =SUMIF(Build!$O$2:$O$25, Table1[[#This Row],[NAME]],Build!$R$2:$R$25) -> 0 | L7: {=_xlfn.LET( _xlpm.val, IF(Table1[[#This Row],[IN BUILD]]>Table1[[#This Row],[LEVELS]],Table1[[#This Row],[LEVELS]],Table1[[#This Row],[IN BUILD]]), IF(_xlpm.val = 0,0, INDIRECT(ADDRESS(ROW(), 6 + (_xlpm.val -1)))) )} -> 0 | N7: THUNDER | P7: =SUMIFS(Table1[APPLIED VALUE],Table1[BUFF TYPE],"FLAT",Table1[TYPE],N7) -> 0 | R7: =SUMIFS(Table1[APPLIED VALUE],Table1[BUFF TYPE],"%",Table1[TYPE],N7) -> 0
A8: Fighting Spirit | B8: 3 | C8: DMG | D8: YES | E8: % | F8: 10 | G8: 15 | H8: 20 | I8: 25 | J8: 30 | K8: =SUMIF(Build!$O$2:$O$25, Table1[[#This Row],[NAME]],Build!$R$2:$R$25) -> 0 | L8: {=_xlfn.LET( _xlpm.val, IF(Table1[[#This Row],[IN BUILD]]>Table1[[#This Row],[LEVELS]],Table1[[#This Row],[LEVELS]],Table1[[#This Row],[IN BUILD]]), IF(_xlpm.val = 0,0, INDIRECT(ADDRESS(ROW(), 6 + (_xlpm.val -1)))) )} -> 0 | N8: ICE | P8: =SUMIFS(Table1[APPLIED VALUE],Table1[BUFF TYPE],"FLAT",Table1[TYPE],N8) -> 0 | R8: =SUMIFS(Table1[APPLIED VALUE],Table1[BUFF TYPE],"%",Table1[TYPE],N8) -> 0
A9: Pursuit | B9: 5 | C9: DMG | D9: YES | E9: % | F9: 10 | G9: 15 | H9: 20 | I9: 30 | J9: 45 | K9: =SUMIF(Build!$O$2:$O$25, Table1[[#This Row],[NAME]],Build!$R$2:$R$25) -> 0 | L9: {=_xlfn.LET( _xlpm.val, IF(Table1[[#This Row],[IN BUILD]]>Table1[[#This Row],[LEVELS]],Table1[[#This Row],[LEVELS]],Table1[[#This Row],[IN BUILD]]), IF(_xlpm.val = 0,0, INDIRECT(ADDRESS(ROW(), 6 + (_xlpm.val -1)))) )} -> 0 | N9: DRAGON | P9: =SUMIFS(Table1[APPLIED VALUE],Table1[BUFF TYPE],"FLAT",Table1[TYPE],N9) -> 0 | R9: =SUMIFS(Table1[APPLIED VALUE],Table1[BUFF TYPE],"%",Table1[TYPE],N9) -> 0
A10: Headstrong | B10: 5 | C10: DMG | D10: YES | E10: % | F10: 10 | G10: 15 | H10: 20 | I10: 30 | J10: 40 | K10: =SUMIF(Build!$O$2:$O$25, Table1[[#This Row],[NAME]],Build!$R$2:$R$25) -> 0 | L10: {=_xlfn.LET( _xlpm.val, IF(Table1[[#This Row],[IN BUILD]]>Table1[[#This Row],[LEVELS]],Table1[[#This Row],[LEVELS]],Table1[[#This Row],[IN BUILD]]), IF(_xlpm.val = 0,0, INDIRECT(ADDRESS(ROW(), 6 + (_xlpm.val -1)))) )} -> 0 | N10: POISON | P10: =SUMIFS(Table1[APPLIED VALUE],Table1[BUFF TYPE],"FLAT",Table1[TYPE],N10) -> 0 | R10: =SUMIFS(Table1[APPLIED VALUE],Table1[BUFF TYPE],"%",Table1[TYPE],N10) -> 0
A11: Focus | B11: 5 | K11: =SUMIF(Build!$O$2:$O$25, Table1[[#This Row],[NAME]],Build!$R$2:$R$25) -> 0 | L11: {=_xlfn.LET( _xlpm.val, IF(Table1[[#This Row],[IN BUILD]]>Table1[[#This Row],[LEVELS]],Table1[[#This Row],[LEVELS]],Table1[[#This Row],[IN BUILD]]), IF(_xlpm.val = 0,0, INDIRECT(ADDRESS(ROW(), 6 + (_xlpm.val -1)))) )} -> 0 | N11: BLAST | P11: =SUMIFS(Table1[APPLIED VALUE],Table1[BUFF TYPE],"FLAT",Table1[TYPE],N11) -> 0 | R11: =SUMIFS(Table1[APPLIED VALUE],Table1[BUFF TYPE],"%",Table1[TYPE],N11) -> 0
A12: Guard | B12: 5 | K12: =SUMIF(Build!$O$2:$O$25, Table1[[#This Row],[NAME]],Build!$R$2:$R$25) -> 0 | L12: {=_xlfn.LET( _xlpm.val, IF(Table1[[#This Row],[IN BUILD]]>Table1[[#This Row],[LEVELS]],Table1[[#This Row],[LEVELS]],Table1[[#This Row],[IN BUILD]]), IF(_xlpm.val = 0,0, INDIRECT(ADDRESS(ROW(), 6 + (_xlpm.val -1)))) )} -> 0 | N12: PARALYSIS | P12: =SUMIFS(Table1[APPLIED VALUE],Table1[BUFF TYPE],"FLAT",Table1[TYPE],N12) -> 0 | R12: =SUMIFS(Table1[APPLIED VALUE],Table1[BUFF TYPE],"%",Table1[TYPE],N12) -> 0
A13: Lock On | B13: 1 | K13: =SUMIF(Build!$O$2:$O$25, Table1[[#This Row],[NAME]],Build!$R$2:$R$25) -> 0 | L13: {=_xlfn.LET( _xlpm.val, IF(Table1[[#This Row],[IN BUILD]]>Table1[[#This Row],[LEVELS]],Table1[[#This Row],[LEVELS]],Table1[[#This Row],[IN BUILD]]), IF(_xlpm.val = 0,0, INDIRECT(ADDRESS(ROW(), 6 + (_xlpm.val -1)))) )} -> 0
A14: Blast Attack | B14: 5 | C14: BLAST | D14: NO | E14: FLAT | K14: =SUMIF(Build!$O$2:$O$25, Table1[[#This Row],[NAME]],Build!$R$2:$R$25) -> 0 | L14: {=_xlfn.LET( _xlpm.val, IF(Table1[[#This Row],[IN BUILD]]>Table1[[#This Row],[LEVELS]],Table1[[#This Row],[LEVELS]],Table1[[#This Row],[IN BUILD]]), IF(_xlpm.val = 0,0, INDIRECT(ADDRESS(ROW(), 6 + (_xlpm.val -1)))) )} -> 0
A15: Dragon Attack | B15: 5 | C15: DRAGON | D15: NO | E15: FLAT | K15: =SUMIF(Build!$O$2:$O$25, Table1[[#This Row],[NAME]],Build!$R$2:$R$25) -> 0 | L15: {=_xlfn.LET( _xlpm.val, IF(Table1[[#This Row],[IN BUILD]]>Table1[[#This Row],[LEVELS]],Table1[[#This Row],[LEVELS]],Table1[[#This Row],[IN BUILD]]), IF(_xlpm.val = 0,0, INDIRECT(ADDRESS(ROW(), 6 + (_xlpm.val -1)))) )} -> 0
A16: Fire Attack | B16: 5 | C16: FIRE | D16: NO | E16: FLAT | K16: =SUMIF(Build!$O$2:$O$25, Table1[[#This Row],[NAME]],Build!$R$2:$R$25) -> 0 | L16: {=_xlfn.LET( _xlpm.val, IF(Table1[[#This Row],[IN BUILD]]>Table1[[#This Row],[LEVELS]],Table1[[#This Row],[LEVELS]],Table1[[#This Row],[IN BUILD]]), IF(_xlpm.val = 0,0, INDIRECT(ADDRESS(ROW(), 6 + (_xlpm.val -1)))) )} -> 0
A17: Water Attack | B17: 5 | C17: WATER | D17: NO | E17: FLAT | K17: =SUMIF(Build!$O$2:$O$25, Table1[[#This Row],[NAME]],Build!$R$2:$R$25) -> 0 | L17: {=_xlfn.LET( _xlpm.val, IF(Table1[[#This Row],[IN BUILD]]>Table1[[#This Row],[LEVELS]],Table1[[#This Row],[LEVELS]],Table1[[#This Row],[IN BUILD]]), IF(_xlpm.val = 0,0, INDIRECT(ADDRESS(ROW(), 6 + (_xlpm.val -1)))) )} -> 0
A18: Ice Attack | B18: 5 | C18: ICE | D18: NO | E18: FLAT | K18: =SUMIF(Build!$O$2:$O$25, Table1[[#This Row],[NAME]],Build!$R$2:$R$25) -> 0 | L18: {=_xlfn.LET( _xlpm.val, IF(Table1[[#This Row],[IN BUILD]]>Table1[[#This Row],[LEVELS]],Table1[[#This Row],[LEVELS]],Table1[[#This Row],[IN BUILD]]), IF(_xlpm.val = 0,0, INDIRECT(ADDRESS(ROW(), 6 + (_xlpm.val -1)))) )} -> 0
A19: Thunder Attack | B19: 5 | C19: THUNDER | D19: NO | E19: FLAT | K19: =SUMIF(Build!$O$2:$O$25, Table1[[#This Row],[NAME]],Build!$R$2:$R$25) -> 0 | L19: {=_xlfn.LET( _xlpm.val, IF(Table1[[#This Row],[IN BUILD]]>Table1[[#This Row],[LEVELS]],Table1[[#This Row],[LEVELS]],Table1[[#This Row],[IN BUILD]]), IF(_xlpm.val = 0,0, INDIRECT(ADDRESS(ROW(), 6 + (_xlpm.val -1)))) )} -> 0
A20: Aggressive Dodger | B20: 5 | C20: DMG | D20: YES | E20: % | K20: =SUMIF(Build!$O$2:$O$25, Table1[[#This Row],[NAME]],Build!$R$2:$R$25) -> 0 | L20: {=_xlfn.LET( _xlpm.val, IF(Table1[[#This Row],[IN BUILD]]>Table1[[#This Row],[LEVELS]],Table1[[#This Row],[LEVELS]],Table1[[#This Row],[IN BUILD]]), IF(_xlpm.val = 0,0, INDIRECT(ADDRESS(ROW(), 6 + (_xlpm.val -1)))) )} -> 0
A21: Ailment Opportunist | B21: 5 | K21: =SUMIF(Build!$O$2:$O$25, Table1[[#This Row],[NAME]],Build!$R$2:$R$25) -> 0 | L21: {=_xlfn.LET( _xlpm.val, IF(Table1[[#This Row],[IN BUILD]]>Table1[[#This Row],[LEVELS]],Table1[[#This Row],[LEVELS]],Table1[[#This Row],[IN BUILD]]), IF(_xlpm.val = 0,0, INDIRECT(ADDRESS(ROW(), 6 + (_xlpm.val -1)))) )} -> 0
A22: Burst | B22: 5 | C22: ATK | E22: % | K22: =SUMIF(Build!$O$2:$O$25, Table1[[#This Row],[NAME]],Build!$R$2:$R$25) -> 0 | L22: {=_xlfn.LET( _xlpm.val, IF(Table1[[#This Row],[IN BUILD]]>Table1[[#This Row],[LEVELS]],Table1[[#This Row],[LEVELS]],Table1[[#This Row],[IN BUILD]]), IF(_xlpm.val = 0,0, INDIRECT(ADDRESS(ROW(), 6 + (_xlpm.val -1)))) )} -> 0
A23: Charge Master | B23: 5 | K23: =SUMIF(Build!$O$2:$O$25, Table1[[#This Row],[NAME]],Build!$R$2:$R$25) -> 0 | L23: {=_xlfn.LET( _xlpm.val, IF(Table1[[#This Row],[IN BUILD]]>Table1[[#This Row],[LEVELS]],Table1[[#This Row],[LEVELS]],Table1[[#This Row],[IN BUILD]]), IF(_xlpm.val = 0,0, INDIRECT(ADDRESS(ROW(), 6 + (_xlpm.val -1)))) )} -> 0
A24: Coalescence | B24: 5 | K24: =SUMIF(Build!$O$2:$O$25, Table1[[#This Row],[NAME]],Build!$R$2:$R$25) -> 0 | L24: {=_xlfn.LET( _xlpm.val, IF(Table1[[#This Row],[IN BUILD]]>Table1[[#This Row],[LEVELS]],Table1[[#This Row],[LEVELS]],Table1[[#This Row],[IN BUILD]]), IF(_xlpm.val = 0,0, INDIRECT(ADDRESS(ROW(), 6 + (_xlpm.val -1)))) )} -> 0
A25: Critical Boost | B25: 5 | K25: =SUMIF(Build!$O$2:$O$25, Table1[[#This Row],[NAME]],Build!$R$2:$R$25) -> 0 | L25: {=_xlfn.LET( _xlpm.val, IF(Table1[[#This Row],[IN BUILD]]>Table1[[#This Row],[LEVELS]],Table1[[#This Row],[LEVELS]],Table1[[#This Row],[IN BUILD]]), IF(_xlpm.val = 0,0, INDIRECT(ADDRESS(ROW(), 6 + (_xlpm.val -1)))) )} -> 0
A26: Critical Eye | B26: 5 | K26: =SUMIF(Build!$O$2:$O$25, Table1[[#This Row],[NAME]],Build!$R$2:$R$25) -> 0 | L26: {=_xlfn.LET( _xlpm.val, IF(Table1[[#This Row],[IN BUILD]]>Table1[[#This Row],[LEVELS]],Table1[[#This Row],[LEVELS]],Table1[[#This Row],[IN BUILD]]), IF(_xlpm.val = 0,0, INDIRECT(ADDRESS(ROW(), 6 + (_xlpm.val -1)))) )} -> 0
A27: Dauntless | B27: 5 | K27: =SUMIF(Build!$O$2:$O$25, Table1[[#This Row],[NAME]],Build!$R$2:$R$25) -> 0 | L27: {=_xlfn.LET( _xlpm.val, IF(Table1[[#This Row],[IN BUILD]]>Table1[[#This Row],[LEVELS]],Table1[[#This Row],[LEVELS]],Table1[[#This Row],[IN BUILD]]), IF(_xlpm.val = 0,0, INDIRECT(ADDRESS(ROW(), 6 + (_xlpm.val -1)))) )} -> 0
A28: Latent Power | B28: 5 | K28: =SUMIF(Build!$O$2:$O$25, Table1[[#This Row],[NAME]],Build!$R$2:$R$25) -> 0 | L28: {=_xlfn.LET( _xlpm.val, IF(Table1[[#This Row],[IN BUILD]]>Table1[[#This Row],[LEVELS]],Table1[[#This Row],[LEVELS]],Table1[[#This Row],[IN BUILD]]), IF(_xlpm.val = 0,0, INDIRECT(ADDRESS(ROW(), 6 + (_xlpm.val -1)))) )} -> 0
A29: Offensive Dodger | B29: 5 | K29: =SUMIF(Build!$O$2:$O$25, Table1[[#This Row],[NAME]],Build!$R$2:$R$25) -> 0 | L29: {=_xlfn.LET( _xlpm.val, IF(Table1[[#This Row],[IN BUILD]]>Table1[[#This Row],[LEVELS]],Table1[[#This Row],[LEVELS]],Table1[[#This Row],[IN BUILD]]), IF(_xlpm.val = 0,0, INDIRECT(ADDRESS(ROW(), 6 + (_xlpm.val -1)))) )} -> 0
A30: Partbreaker | B30: 5 | K30: =SUMIF(Build!$O$2:$O$25, Table1[[#This Row],[NAME]],Build!$R$2:$R$25) -> 0 | L30: {=_xlfn.LET( _xlpm.val, IF(Table1[[#This Row],[IN BUILD]]>Table1[[#This Row],[LEVELS]],Table1[[#This Row],[LEVELS]],Table1[[#This Row],[IN BUILD]]), IF(_xlpm.val = 0,0, INDIRECT(ADDRESS(ROW(), 6 + (_xlpm.val -1)))) )} -> 0
A31: Raw Power | B31: 5 | K31: =SUMIF(Build!$O$2:$O$25, Table1[[#This Row],[NAME]],Build!$R$2:$R$25) -> 0 | L31: {=_xlfn.LET( _xlpm.val, IF(Table1[[#This Row],[IN BUILD]]>Table1[[#This Row],[LEVELS]],Table1[[#This Row],[LEVELS]],Table1[[#This Row],[IN BUILD]]), IF(_xlpm.val = 0,0, INDIRECT(ADDRESS(ROW(), 6 + (_xlpm.val -1)))) )} -> 0
A32: Resuscitate | B32: 5 | K32: =SUMIF(Build!$O$2:$O$25, Table1[[#This Row],[NAME]],Build!$R$2:$R$25) -> 0 | L32: {=_xlfn.LET( _xlpm.val, IF(Table1[[#This Row],[IN BUILD]]>Table1[[#This Row],[LEVELS]],Table1[[#This Row],[LEVELS]],Table1[[#This Row],[IN BUILD]]), IF(_xlpm.val = 0,0, INDIRECT(ADDRESS(ROW(), 6 + (_xlpm.val -1)))) )} -> 0
A33: Special Boost | B33: 5 | K33: =SUMIF(Build!$O$2:$O$25, Table1[[#This Row],[NAME]],Build!$R$2:$R$25) -> 0 | L33: {=_xlfn.LET( _xlpm.val, IF(Table1[[#This Row],[IN BUILD]]>Table1[[#This Row],[LEVELS]],Table1[[#This Row],[LEVELS]],Table1[[#This Row],[IN BUILD]]), IF(_xlpm.val = 0,0, INDIRECT(ADDRESS(ROW(), 6 + (_xlpm.val -1)))) )} -> 0
A34: Special Partbreaker | B34: 5 | K34: =SUMIF(Build!$O$2:$O$25, Table1[[#This Row],[NAME]],Build!$R$2:$R$25) -> 0 | L34: {=_xlfn.LET( _xlpm.val, IF(Table1[[#This Row],[IN BUILD]]>Table1[[#This Row],[LEVELS]],Table1[[#This Row],[LEVELS]],Table1[[#This Row],[IN BUILD]]), IF(_xlpm.val = 0,0, INDIRECT(ADDRESS(ROW(), 6 + (_xlpm.val -1)))) )} -> 0
... A115: Windproof | B115: 3 | K115: =SUMIF(Build!$O$2:$O$25, Table1[[#This Row],[NAME]],Build!$R$2:$R$25) -> 0 | L115: {=_xlfn.LET( _xlpm.val, IF(Table1[[#This Row],[IN BUILD]]>Table1[[#This Row],[LEVELS]],Table1[[#This Row],[LEVELS]],Table1[[#This Row],[IN BUILD]]), IF(_xlpm.val = 0,0, INDIRECT(ADDRESS(ROW(), 6 + (_xlpm.val -1)))) )} -> 0

Sheet Helmets
A1: ALLOY | D1: GRADE 1 | G1: GRADE 2 | J1: GRADE 3 | M1: GRADE 4 | P1: GRADE 5 | S1: GRADE 6 | V1: GRADE 7 | Y1: GRADE 8 | AB1: GRADE 9 | AE1: GRADE 10
C2: DEF | D2: 0 | G2: 0 | J2: 0 | M2: 0 | P2: 0 | S2: 0 | V2: 0 | Y2: 0 | AB2: 0 | AE2: 0
C3: DRIFT | D3: 0 | G3: 0 | J3: 0 | M3: 0 | P3: 0 | S3: 0 | V3: 0 | Y3: 0 | AB3: 0 | AE3: 0
C4: SKILL
A9: LEATHER | D9: GRADE 1 | G9: GRADE 2 | J9: GRADE 3 | M9: GRADE 4 | P9: GRADE 5 | S9: GRADE 6 | V9: GRADE 7 | Y9: GRADE 8 | AB9: GRADE 9 | AE9: GRADE 10
C10: DEF | D10: 0 | G10: 0 | J10: 0 | M10: 0 | P10: 0 | S10: 0 | V10: 0 | Y10: 0 | AB10: 0 | AE10: 0
C11: DRIFT | D11: 0 | G11: 0 | J11: 0 | M11: 0 | P11: 0 | S11: 0 | V11: 0 | Y11: 0 | AB11: 0 | AE11: 0
C12: SKILL
A17: GREAT JAGRAS | D17: GRADE 1 | G17: GRADE 2 | J17: GRADE 3 | M17: GRADE 4 | P17: GRADE 5 | S17: GRADE 6 | V17: GRADE 7 | Y17: GRADE 8 | AB17: GRADE 9 | AE17: GRADE 10
C18: DEF | D18: 0 | G18: 0 | J18: 0 | M18: 0 | P18: 0 | S18: 0 | V18: 0 | Y18: 0 | AB18: 0 | AE18: 0
C19: DRIFT | D19: 0 | G19: 0 | J19: 0 | M19: 0 | P19: 0 | S19: 0 | V19: 0 | Y19: 0 | AB19: 0 | AE19: 0
C20: SKILL
A25: KULU-YA-KU | D25: GRADE 1 | G25: GRADE 2 | J25: GRADE 3 | M25: GRADE 4 | P25: GRADE 5 | S25: GRADE 6 | V25: GRADE 7 | Y25: GRADE 8 | AB25: GRADE 9 | AE25: GRADE 10
C26: DEF | D26: 0 | G26: 0 | J26: 0 | M26: 0 | P26: 0 | S26: 0 | V26: 0 | Y26: 0 | AB26: 0 | AE26: 0
C27: DRIFT | D27: 0 | G27: 0 | J27: 0 | M27: 0 | P27: 0 | S27: 0 | V27: 0 | Y27: 0 | AB27: 0 | AE27: 0
C28: SKILL
A33: PUKEI-PUKEI | D33: GRADE 1 | G33: GRADE 2 | J33: GRADE 3 | M33: GRADE 4 | P33: GRADE 5 | S33: GRADE 6 | V33: GRADE 7 | Y33: GRADE 8 | AB33: GRADE 9 | AE33: GRADE 10
C34: DEF | D34: 0 | G34: 0 | J34: 0 | M34: 0 | P34: 0 | S34: 0 | V34: 0 | Y34: 0 | AB34: 0 | AE34: 0
C35: DRIFT | D35: 0 | G35: 0 | J35: 0 | M35: 0 | P35: 0 | S35: 0 | V35: 0 | Y35: 0 | AB35: 0 | AE35: 0
C36: SKILL
A41: CORAL PUKEI-PUKEI | D41: GRADE 1 | G41: GRADE 2 | J41: GRADE 3 | M41: GRADE 4 | P41: GRADE 5 | S41: GRADE 6 | V41: GRADE 7 | Y41: GRADE 8 | AB41: GRADE 9 | AE41: GRADE 10
C42: DEF | D42: 0 | G42: 0 | J42: 0 | M42: 0 | P42: 0 | S42: 0 | V42: 0 | Y42: 0 | AB42: 0 | AE42: 0
C43: DRIFT | D43: 0 | G43: 0 | J43: 0 | M43: 0 | P43: 0 | S43: 0 | V43: 0 | Y43: 0 | AB43: 0 | AE43: 0
C44: SKILL
A49: BARROTH | D49: GRADE 1 | G49: GRADE 2 | J49: GRADE 3 | M49: GRADE 4 | P49: GRADE 5 | S49: GRADE 6 | V49: GRADE 7 | Y49: GRADE 8 | AB49: GRADE 9 | AE49: GRADE 10
C50: DEF | D50: 0 | G50: 0 | J50: 0 | M50: 0 | P50: 0 | S50: 0 | V50: 0 | Y50: 0 | AB50: 0 | AE50: 0
C51: DRIFT | D51: 0 | G51: 0 | J51: 0 | M51: 0 | P51: 0 | S51: 0 | V51: 0 | Y51: 0 | AB51: 0 | AE51: 0
C52: SKILL
A57: GREAT GIRROS | D57: GRADE 1 | G57: GRADE 2 | J57: GRADE 3 | M57: GRADE 4 | P57: GRADE 5 | S57: GRADE 6 | V57: GRADE 7 | Y57: GRADE 8 | AB57: GRADE 9 | AE57: GRADE 10
C58: DEF | D58: 0 | G58: 0 | J58: 0 | M58: 0 | P58: 0 | S58: 0 | V58: 0 | Y58: 0 | AB58: 0 | AE58: 0
C59: DRIFT | D59: 0 | G59: 0 | J59: 0 | M59: 0 | P59: 0 | S59: 0 | V59: 0 | Y59: 0 | AB59: 0 | AE59: 0
C60: SKILL
A65: TOBI-KADACHI | D65: GRADE 1 | G65: GRADE 2 | J65: GRADE 3 | M65: GRADE 4 | P65: GRADE 5 | S65: GRADE 6 | V65: GRADE 7 | Y65: GRADE 8 | AB65: GRADE 9 | AE65: GRADE 10
C66: DEF | D66: 0 | G66: 0 | J66: 0 | M66: 0 | P66: 0 | S66: 0 | V66: 0 | Y66: 0 | AB66: 0 | AE66: 0
C67: DRIFT | D67: 0 | G67: 0 | J67: 0 | M67: 0 | P67: 0 | S67: 0 | V67: 0 | Y67: 0 | AB67: 0 | AE67: 0
C68: SKILL
A73: PAOLUMU | D73: GRADE 1 | G73: GRADE 2 | J73: GRADE 3 | M73: GRADE 4 | P73: GRADE 5 | S73: GRADE 6 | V73: GRADE 7 | Y73: GRADE 8 | AB73: GRADE 9 | AE73: GRADE 10
C74: DEF | D74: 0 | G74: 0 | J74: 0 | M74: 0 | P74: 0 | S74: 0 | V74: 0 | Y74: 0 | AB74: 0 | AE74: 0
C75: DRIFT | D75: 0 | G75: 0 | J75: 0 | M75: 0 | P75: 0 | S75: 0 | V75: 0 | Y75: 0 | AB75: 0 | AE75: 0
C76: SKILL
...

Sheet Bodies
A1: ALLOY | D1: GRADE 1 | G1: GRADE 2 | J1: GRADE 3 | M1: GRADE 4 | P1: GRADE 5 | S1: GRADE 6 | V1: GRADE 7 | Y1: GRADE 8 | AB1: GRADE 9 | AE1: GRADE 10
C2: DEF | D2: 0 | G2: 0 | J2: 0 | M2: 0 | P2: 0 | S2: 0 | V2: 0 | Y2: 0 | AB2: 0 | AE2: 0
C3: DRIFT | D3: 0 | G3: 0 | J3: 0 | M3: 0 | P3: 0 | S3: 0 | V3: 0 | Y3: 0 | AB3: 0 | AE3: 0
C4: SKILL
A9: LEATHER | D9: GRADE 1 | G9: GRADE 2 | J9: GRADE 3 | M9: GRADE 4 | P9: GRADE 5 | S9: GRADE 6 | V9: GRADE 7 | Y9: GRADE 8 | AB9: GRADE 9 | AE9: GRADE 10
C10: DEF | D10: 0 | G10: 0 | J10: 0 | M10: 0 | P10: 0 | S10: 0 | V10: 0 | Y10: 0 | AB10: 0 | AE10: 0
C11: DRIFT | D11: 0 | G11: 0 | J11: 0 | M11: 0 | P11: 0 | S11: 0 | V11: 0 | Y11: 0 | AB11: 0 | AE11: 0
C12: SKILL
A17: GREAT JAGRAS | D17: GRADE 1 | G17: GRADE 2 | J17: GRADE 3 | M17: GRADE 4 | P17: GRADE 5 | S17: GRADE 6 | V17: GRADE 7 | Y17: GRADE 8 | AB17: GRADE 9 | AE17: GRADE 10
C18: DEF | D18: 0 | G18: 0 | J18: 0 | M18: 0 | P18: 0 | S18: 0 | V18: 0 | Y18: 0 | AB18: 0 | AE18: 0
C19: DRIFT | D19: 0 | G19: 0 | J19: 0 | M19: 0 | P19: 0 | S19: 0 | V19: 0 | Y19: 0 | AB19: 0 | AE19: 0
C20: SKILL
A25: KULU-YA-KU | D25: GRADE 1 | G25: GRADE 2 | J25: GRADE 3 | M25: GRADE 4 | P25: GRADE 5 | S25: GRADE 6 | V25: GRADE 7 | Y25: GRADE 8 | AB25: GRADE 9 | AE25: GRADE 10
C26: DEF | D26: 0 | G26: 0 | J26: 0 | M26: 0 | P26: 0 | S26: 0 | V26: 0 | Y26: 0 | AB26: 0 | AE26: 0
C27: DRIFT | D27: 0 | G27: 0 | J27: 0 | M27: 0 | P27: 0 | S27: 0 | V27: 0 | Y27: 0 | AB27: 0 | AE27: 0
C28: SKILL
A33: PUKEI-PUKEI | D33: GRADE 1 | G33: GRADE 2 | J33: GRADE 3 | M33: GRADE 4 | P33: GRADE 5 | S33: GRADE 6 | V33: GRADE 7 | Y33: GRADE 8 | AB33: GRADE 9 | AE33: GRADE 10
C34: DEF | D34: 0 | G34: 0 | J34: 0 | M34: 0 | P34: 0 | S34: 0 | V34: 0 | Y34: 0 | AB34: 0 | AE34: 0
C35: DRIFT | D35: 0 | G35: 0 | J35: 0 | M35: 0 | P35: 0 | S35: 0 | V35: 0 | Y35: 0 | AB35: 0 | AE35: 0
C36: SKILL
A41: CORAL PUKEI-PUKEI | D41: GRADE 1 | G41: GRADE 2 | J41: GRADE 3 | M41: GRADE 4 | P41: GRADE 5 | S41: GRADE 6 | V41: GRADE 7 | Y41: GRADE 8 | AB41: GRADE 9 | AE41: GRADE 10
C42: DEF | D42: 0 | G42: 0 | J42: 0 | M42: 0 | P42: 0 | S42: 0 | V42: 0 | Y42: 0 | AB42: 0 | AE42: 0
C43: DRIFT | D43: 0 | G43: 0 | J43: 0 | M43: 0 | P43: 0 | S43: 0 | V43: 0 | Y43: 0 | AB43: 0 | AE43: 0
C44: SKILL
A49: BARROTH | D49: GRADE 1 | G49: GRADE 2 | J49: GRADE 3 | M49: GRADE 4 | P49: GRADE 5 | S49: GRADE 6 | V49: GRADE 7 | Y49: GRADE 8 | AB49: GRADE 9 | AE49: GRADE 10
C50: DEF | D50: 0 | G50: 0 | J50: 0 | M50: 0 | P50: 0 | S50: 0 | V50: 0 | Y50: 0 | AB50: 0 | AE50: 0
C51: DRIFT | D51: 0 | G51: 0 | J51: 0 | M51: 0 | P51: 0 | S51: 0 | V51: 0 | Y51: 0 | AB51: 0 | AE51: 0
C52: SKILL
A57: GREAT GIRROS | D57: GRADE 1 | G57: GRADE 2 | J57: GRADE 3 | M57: GRADE 4 | P57: GRADE 5 | S57: GRADE 6 | V57: GRADE 7 | Y57: GRADE 8 | AB57: GRADE 9 | AE57: GRADE 10
C58: DEF | D58: 0 | G58: 0 | J58: 0 | M58: 0 | P58: 0 | S58: 0 | V58: 0 | Y58: 0 | AB58: 0 | AE58: 0
C59: DRIFT | D59: 0 | G59: 0 | J59: 0 | M59: 0 | P59: 0 | S59: 0 | V59: 0 | Y59: 0 | AB59: 0 | AE59: 0
C60: SKILL
A65: TOBI-KADACHI | D65: GRADE 1 | G65: GRADE 2 | J65: GRADE 3 | M65: GRADE 4 | P65: GRADE 5 | S65: GRADE 6 | V65: GRADE 7 | Y65: GRADE 8 | AB65: GRADE 9 | AE65: GRADE 10
C66: DEF | D66: 0 | G66: 0 | J66: 0 | M66: 0 | P66: 0 | S66: 0 | V66: 0 | Y66: 0 | AB66: 0 | AE66: 0
C67: DRIFT | D67: 0 | G67: 0 | J67: 0 | M67: 0 | P67: 0 | S67: 0 | V67: 0 | Y67: 0 | AB67: 0 | AE67: 0
C68: SKILL
A73: PAOLUMU | D73: GRADE 1 | G73: GRADE 2 | J73: GRADE 3 | M73: GRADE 4 | P73: GRADE 5 | S73: GRADE 6 | V73: GRADE 7 | Y73: GRADE 8 | AB73: GRADE 9 | AE73: GRADE 10
C74: DEF | D74: 0 | G74: 0 | J74: 0 | M74: 0 | P74: 0 | S74: 0 | V74: 0 | Y74: 0 | AB74: 0 | AE74: 0
C75: DRIFT | D75: 0 | G75: 0 | J75: 0 | M75: 0 | P75: 0 | S75: 0 | V75: 0 | Y75: 0 | AB75: 0 | AE75: 0
C76: SKILL
...

Sheet Arms
A1: ALLOY | D1: GRADE 1 | G1: GRADE 2 | J1: GRADE 3 | M1: GRADE 4 | P1: GRADE 5 | S1: GRADE 6 | V1: GRADE 7 | Y1: GRADE 8 | AB1: GRADE 9 | AE1: GRADE 10
C2: DEF | D2: 0 | G2: 0 | J2: 0 | M2: 0 | P2: 0 | S2: 0 | V2: 0 | Y2: 0 | AB2: 0 | AE2: 0
C3: DRIFT | D3: 0 | G3: 0 | J3: 0 | M3: 0 | P3: 0 | S3: 0 | V3: 0 | Y3: 0 | AB3: 0 | AE3: 0
C4: SKILL
A9: LEATHER | D9: GRADE 1 | G9: GRADE 2 | J9: GRADE 3 | M9: GRADE 4 | P9: GRADE 5 | S9: GRADE 6 | V9: GRADE 7 | Y9: GRADE 8 | AB9: GRADE 9 | AE9: GRADE 10
C10: DEF | D10: 0 | G10: 0 | J10: 0 | M10: 0 | P10: 0 | S10: 0 | V10: 0 | Y10: 0 | AB10: 0 | AE10: 0
C11: DRIFT | D11: 0 | G11: 0 | J11: 0 | M11: 0 | P11: 0 | S11: 0 | V11: 0 | Y11: 0 | AB11: 0 | AE11: 0
C12: SKILL
A17: GREAT JAGRAS | D17: GRADE 1 | G17: GRADE 2 | J17: GRADE 3 | M17: GRADE 4 | P17: GRADE 5 | S17: GRADE 6 | V17: GRADE 7 | Y17: GRADE 8 | AB17: GRADE 9 | AE17: GRADE 10
C18: DEF | D18: 0 | G18: 0 | J18: 0 | M18: 0 | P18: 0 | S18: 0 | V18: 0 | Y18: 0 | AB18: 0 | AE18: 0
C19: DRIFT | D19: 0 | G19: 0 | J19: 0 | M19: 0 | P19: 0 | S19: 0 | V19: 0 | Y19: 0 | AB19: 0 | AE19: 0
C20: SKILL
A25: KULU-YA-KU | D25: GRADE 1 | G25: GRADE 2 | J25: GRADE 3 | M25: GRADE 4 | P25: GRADE 5 | S25: GRADE 6 | V25: GRADE 7 | Y25: GRADE 8 | AB25: GRADE 9 | AE25: GRADE 10
C26: DEF | D26: 0 | G26: 0 | J26: 0 | M26: 0 | P26: 0 | S26: 0 | V26: 0 | Y26: 0 | AB26: 0 | AE26: 0
C27: DRIFT | D27: 0 | G27: 0 | J27: 0 | M27: 0 | P27: 0 | S27: 0 | V27: 0 | Y27: 0 | AB27: 0 | AE27: 0
C28: SKILL
A33: PUKEI-PUKEI | D33: GRADE 1 | G33: GRADE 2 | J33: GRADE 3 | M33: GRADE 4 | P33: GRADE 5 | S33: GRADE 6 | V33: GRADE 7 | Y33: GRADE 8 | AB33: GRADE 9 | AE33: GRADE 10
C34: DEF | D34: 0 | G34: 0 | J34: 0 | M34: 0 | P34: 0 | S34: 0 | V34: 0 | Y34: 0 | AB34: 0 | AE34: 0
C35: DRIFT | D35: 0 | G35: 0 | J35: 0 | M35: 0 | P35: 0 | S35: 0 | V35: 0 | Y35: 0 | AB35: 0 | AE35: 0
C36: SKILL
A41: CORAL PUKEI-PUKEI | D41: GRADE 1 | G41: GRADE 2 | J41: GRADE 3 | M41: GRADE 4 | P41: GRADE 5 | S41: GRADE 6 | V41: GRADE 7 | Y41: GRADE 8 | AB41: GRADE 9 | AE41: GRADE 10
C42: DEF | D42: 0 | G42: 0 | J42: 0 | M42: 0 | P42: 0 | S42: 0 | V42: 0 | Y42: 0 | AB42: 0 | AE42: 0
C43: DRIFT | D43: 0 | G43: 0 | J43: 0 | M43: 0 | P43: 0 | S43: 0 | V43: 0 | Y43: 0 | AB43: 0 | AE43: 0
C44: SKILL
A49: BARROTH | D49: GRADE 1 | G49: GRADE 2 | J49: GRADE 3 | M49: GRADE 4 | P49: GRADE 5 | S49: GRADE 6 | V49: GRADE 7 | Y49: GRADE 8 | AB49: GRADE 9 | AE49: GRADE 10
C50: DEF | D50: 0 | G50: 0 | J50: 0 | M50: 0 | P50: 0 | S50: 0 | V50: 0 | Y50: 0 | AB50: 0 | AE50: 0
C51: DRIFT | D51: 0 | G51: 0 | J51: 0 | M51: 0 | P51: 0 | S51: 0 | V51: 0 | Y51: 0 | AB51: 0 | AE51: 0
C52: SKILL
A57: GREAT GIRROS | D57: GRADE 1 | G57: GRADE 2 | J57: GRADE 3 | M57: GRADE 4 | P57: GRADE 5 | S57: GRADE 6 | V57: GRADE 7 | Y57: GRADE 8 | AB57: GRADE 9 | AE57: GRADE 10
C58: DEF | D58: 0 | G58: 0 | J58: 0 | M58: 0 | P58: 0 | S58: 0 | V58: 0 | Y58: 0 | AB58: 0 | AE58: 0
C59: DRIFT | D59: 0 | G59: 0 | J59: 0 | M59: 0 | P59: 0 | S59: 0 | V59: 0 | Y59: 0 | AB59: 0 | AE59: 0
C60: SKILL
A65: TOBI-KADACHI | D65: GRADE 1 | G65: GRADE 2 | J65: GRADE 3 | M65: GRADE 4 | P65: GRADE 5 | S65: GRADE 6 | V65: GRADE 7 | Y65: GRADE 8 | AB65: GRADE 9 | AE65: GRADE 10
C66: DEF | D66: 0 | G66: 0 | J66: 0 | M66: 0 | P66: 0 | S66: 0 | V66: 0 | Y66: 0 | AB66: 0 | AE66: 0
C67: DRIFT | D67: 0 | G67: 0 | J67: 0 | M67: 0 | P67: 0 | S67: 0 | V67: 0 | Y67: 0 | AB67: 0 | AE67: 0
C68: SKILL
A73: PAOLUMU | D73: GRADE 1 | G73: GRADE 2 | J73: GRADE 3 | M73: GRADE 4 | P73: GRADE 5 | S73: GRADE 6 | V73: GRADE 7 | Y73: GRADE 8 | AB73: GRADE 9 | AE73: GRADE 10
C74: DEF | D74: 0 | G74: 0 | J74: 0 | M74: 0 | P74: 0 | S74: 0 | V74: 0 | Y74: 0 | AB74: 0 | AE74: 0
C75: DRIFT | D75: 0 | G75: 0 | J75: 0 | M75: 0 | P75: 0 | S75: 0 | V75: 0 | Y75: 0 | AB75: 0 | AE75: 0
C76: SKILL
...

Sheet Waists
A1: ALLOY | D1: GRADE 1 | G1: GRADE 2 | J1: GRADE 3 | M1: GRADE 4 | P1: GRADE 5 | S1: GRADE 6 | V1: GRADE 7 | Y1: GRADE 8 | AB1: GRADE 9 | AE1: GRADE 10
C2: DEF | D2: 0 | G2: 0 | J2: 0 | M2: 0 | P2: 0 | S2: 0 | V2: 0 | Y2: 0 | AB2: 0 | AE2: 0
C3: DRIFT | D3: 0 | G3: 0 | J3: 0 | M3: 0 | P3: 0 | S3: 0 | V3: 0 | Y3: 0 | AB3: 0 | AE3: 0
C4: SKILL
A9: LEATHER | D9: GRADE 1 | G9: GRADE 2 | J9: GRADE 3 | M9: GRADE 4 | P9: GRADE 5 | S9: GRADE 6 | V9: GRADE 7 | Y9: GRADE 8 | AB9: GRADE 9 | AE9: GRADE 10
C10: DEF | D10: 0 | G10: 0 | J10: 0 | M10: 0 | P10: 0 | S10: 0 | V10: 0 | Y10: 0 | AB10: 0 | AE10: 0
C11: DRIFT | D11: 0 | G11: 0 | J11: 0 | M11: 0 | P11: 0 | S11: 0 | V11: 0 | Y11: 0 | AB11: 0 | AE11: 0
C12: SKILL
A17: GREAT JAGRAS | D17: GRADE 1 | G17: GRADE 2 | J17: GRADE 3 | M17: GRADE 4 | P17: GRADE 5 | S17: GRADE 6 | V17: GRADE 7 | Y17: GRADE 8 | AB17: GRADE 9 | AE17: GRADE 10
C18: DEF | D18: 0 | G18: 0 | J18: 0 | M18: 0 | P18: 0 | S18: 0 | V18: 0 | Y18: 0 | AB18: 0 | AE18: 0
C19: DRIFT | D19: 0 | G19: 0 | J19: 0 | M19: 0 | P19: 0 | S19: 0 | V19: 0 | Y19: 0 | AB19: 0 | AE19: 0
C20: SKILL
A25: KULU-YA-KU | D25: GRADE 1 | G25: GRADE 2 | J25: GRADE 3 | M25: GRADE 4 | P25: GRADE 5 | S25: GRADE 6 | V25: GRADE 7 | Y25: GRADE 8 | AB25: GRADE 9 | AE25: GRADE 10
C26: DEF | D26: 0 | G26: 0 | J26: 0 | M26: 0 | P26: 0 | S26: 0 | V26: 0 | Y26: 0 | AB26: 0 | AE26: 0
C27: DRIFT | D27: 0 | G27: 0 | J27: 0 | M27: 0 | P27: 0 | S27: 0 | V27: 0 | Y27: 0 | AB27: 0 | AE27: 0
C28: SKILL
A33: PUKEI-PUKEI | D33: GRADE 1 | G33: GRADE 2 | J33: GRADE 3 | M33: GRADE 4 | P33: GRADE 5 | S33: GRADE 6 | V33: GRADE 7 | Y33: GRADE 8 | AB33: GRADE 9 | AE33: GRADE 10
C34: DEF | D34: 0 | G34: 0 | J34: 0 | M34: 0 | P34: 0 | S34: 0 | V34: 0 | Y34: 0 | AB34: 0 | AE34: 0
C35: DRIFT | D35: 0 | G35: 0 | J35: 0 | M35: 0 | P35: 0 | S35: 0 | V35: 0 | Y35: 0 | AB35: 0 | AE35: 0
C36: SKILL
A41: CORAL PUKEI-PUKEI | D41: GRADE 1 | G41: GRADE 2 | J41: GRADE 3 | M41: GRADE 4 | P41: GRADE 5 | S41: GRADE 6 | V41: GRADE 7 | Y41: GRADE 8 | AB41: GRADE 9 | AE41: GRADE 10
C42: DEF | D42: 0 | G42: 0 | J42: 0 | M42: 0 | P42: 0 | S42: 0 | V42: 0 | Y42: 0 | AB42: 0 | AE42: 0
C43: DRIFT | D43: 0 | G43: 0 | J43: 0 | M43: 0 | P43: 0 | S43: 0 | V43: 0 | Y43: 0 | AB43: 0 | AE43: 0
C44: SKILL
A49: BARROTH | D49: GRADE 1 | G49: GRADE 2 | J49: GRADE 3 | M49: GRADE 4 | P49: GRADE 5 | S49: GRADE 6 | V49: GRADE 7 | Y49: GRADE 8 | AB49: GRADE 9 | AE49: GRADE 10
C50: DEF | D50: 0 | G50: 0 | J50: 0 | M50: 0 | P50: 0 | S50: 0 | V50: 0 | Y50: 0 | AB50: 0 | AE50: 0
C51: DRIFT | D51: 0 | G51: 0 | J51: 0 | M51: 0 | P51: 0 | S51: 0 | V51: 0 | Y51: 0 | AB51: 0 | AE51: 0
C52: SKILL
A57: GREAT GIRROS | D57: GRADE 1 | G57: GRADE 2 | J57: GRADE 3 | M57: GRADE 4 | P57: GRADE 5 | S57: GRADE 6 | V57: GRADE 7 | Y57: GRADE 8 | AB57: GRADE 9 | AE57: GRADE 10
C58: DEF | D58: 0 | G58: 0 | J58: 0 | M58: 0 | P58: 0 | S58: 0 | V58: 0 | Y58: 0 | AB58: 0 | AE58: 0
C59: DRIFT | D59: 0 | G59: 0 | J59: 0 | M59: 0 | P59: 0 | S59: 0 | V59: 0 | Y59: 0 | AB59: 0 | AE59: 0
C60: SKILL
A65: TOBI-KADACHI | D65: GRADE 1 | G65: GRADE 2 | J65: GRADE 3 | M65: GRADE 4 | P65: GRADE 5 | S65: GRADE 6 | V65: GRADE 7 | Y65: GRADE 8 | AB65: GRADE 9 | AE65: GRADE 10
C66: DEF | D66: 0 | G66: 0 | J66: 0 | M66: 0 | P66: 0 | S66: 0 | V66: 0 | Y66: 0 | AB66: 0 | AE66: 0
C67: DRIFT | D67: 0 | G67: 0 | J67: 0 | M67: 0 | P67: 0 | S67: 0 | V67: 0 | Y67: 0 | AB67: 0 | AE67: 0
C68: SKILL
A73: PAOLUMU | D73: GRADE 1 | G73: GRADE 2 | J73: GRADE 3 | M73: GRADE 4 | P73: GRADE 5 | S73: GRADE 6 | V73: GRADE 7 | Y73: GRADE 8 | AB73: GRADE 9 | AE73: GRADE 10
C74: DEF | D74: 0 | G74: 0 | J74: 0 | M74: 0 | P74: 0 | S74: 0 | V74: 0 | Y74: 0 | AB74: 0 | AE74: 0
C75: DRIFT | D75: 0 | G75: 0 | J75: 0 | M75: 0 | P75: 0 | S75: 0 | V75: 0 | Y75: 0 | AB75: 0 | AE75: 0
C76: SKILL
...

Sheet Legs
A1: ALLOY | D1: GRADE 1 | G1: GRADE 2 | J1: GRADE 3 | M1: GRADE 4 | P1: GRADE 5 | S1: GRADE 6 | V1: GRADE 7 | Y1: GRADE 8 | AB1: GRADE 9 | AE1: GRADE 10
C2: DEF | D2: 0 | G2: 0 | J2: 0 | M2: 0 | P2: 0 | S2: 0 | V2: 0 | Y2: 0 | AB2: 0 | AE2: 0
C3: DRIFT | D3: 0 | G3: 0 | J3: 0 | M3: 0 | P3: 0 | S3: 0 | V3: 0 | Y3: 0 | AB3: 0 | AE3: 0
C4: SKILL
A9: LEATHER | D9: GRADE 1 | G9: GRADE 2 | J9: GRADE 3 | M9: GRADE 4 | P9: GRADE 5 | S9: GRADE 6 | V9: GRADE 7 | Y9: GRADE 8 | AB9: GRADE 9 | AE9: GRADE 10
C10: DEF | D10: 0 | G10: 0 | J10: 0 | M10: 0 | P10: 0 | S10: 0 | V10: 0 | Y10: 0 | AB10: 0 | AE10: 0
C11: DRIFT | D11: 0 | G11: 0 | J11: 0 | M11: 0 | P11: 0 | S11: 0 | V11: 0 | Y11: 0 | AB11: 0 | AE11: 0
C12: SKILL
A17: GREAT JAGRAS | D17: GRADE 1 | G17: GRADE 2 | J17: GRADE 3 | M17: GRADE 4 | P17: GRADE 5 | S17: GRADE 6 | V17: GRADE 7 | Y17: GRADE 8 | AB17: GRADE 9 | AE17: GRADE 10
C18: DEF | D18: 0 | G18: 0 | J18: 0 | M18: 0 | P18: 0 | S18: 0 | V18: 0 | Y18: 0 | AB18: 0 | AE18: 0
C19: DRIFT | D19: 0 | G19: 0 | J19: 0 | M19: 0 | P19: 0 | S19: 0 | V19: 0 | Y19: 0 | AB19: 0 | AE19: 0
C20: SKILL
A25: KULU-YA-KU | D25: GRADE 1 | G25: GRADE 2 | J25: GRADE 3 | M25: GRADE 4 | P25: GRADE 5 | S25: GRADE 6 | V25: GRADE 7 | Y25: GRADE 8 | AB25: GRADE 9 | AE25: GRADE 10
C26: DEF | D26: 0 | G26: 0 | J26: 0 | M26: 0 | P26: 0 | S26: 0 | V26: 0 | Y26: 0 | AB26: 0 | AE26: 0
C27: DRIFT | D27: 0 | G27: 0 | J27: 0 | M27: 0 | P27: 0 | S27: 0 | V27: 0 | Y27: 0 | AB27: 0 | AE27: 0
C28: SKILL
A33: PUKEI-PUKEI | D33: GRADE 1 | G33: GRADE 2 | J33: GRADE 3 | M33: GRADE 4 | P33: GRADE 5 | S33: GRADE 6 | V33: GRADE 7 | Y33: GRADE 8 | AB33: GRADE 9 | AE33: GRADE 10
C34: DEF | D34: 0 | G34: 0 | J34: 0 | M34: 0 | P34: 0 | S34: 0 | V34: 0 | Y34: 0 | AB34: 0 | AE34: 0
C35: DRIFT | D35: 0 | G35: 0 | J35: 0 | M35: 0 | P35: 0 | S35: 0 | V35: 0 | Y35: 0 | AB35: 0 | AE35: 0
C36: SKILL
A41: CORAL PUKEI-PUKEI | D41: GRADE 1 | G41: GRADE 2 | J41: GRADE 3 | M41: GRADE 4 | P41: GRADE 5 | S41: GRADE 6 | V41: GRADE 7 | Y41: GRADE 8 | AB41: GRADE 9 | AE41: GRADE 10
C42: DEF | D42: 0 | G42: 0 | J42: 0 | M42: 0 | P42: 0 | S42: 0 | V42: 0 | Y42: 0 | AB42: 0 | AE42: 0
C43: DRIFT | D43: 0 | G43: 0 | J43: 0 | M43: 0 | P43: 0 | S43: 0 | V43: 0 | Y43: 0 | AB43: 0 | AE43: 0
C44: SKILL
A49: BARROTH | D49: GRADE 1 | G49: GRADE 2 | J49: GRADE 3 | M49: GRADE 4 | P49: GRADE 5 | S49: GRADE 6 | V49: GRADE 7 | Y49: GRADE 8 | AB49: GRADE 9 | AE49: GRADE 10
C50: DEF | D50: 0 | G50: 0 | J50: 0 | M50: 0 | P50: 0 | S50: 0 | V50: 0 | Y50: 0 | AB50: 0 | AE50: 0
C51: DRIFT | D51: 0 | G51: 0 | J51: 0 | M51: 0 | P51: 0 | S51: 0 | V51: 0 | Y51: 0 | AB51: 0 | AE51: 0
C52: SKILL
A57: GREAT GIRROS | D57: GRADE 1 | G57: GRADE 2 | J57: GRADE 3 | M57: GRADE 4 | P57: GRADE 5 | S57: GRADE 6 | V57: GRADE 7 | Y57: GRADE 8 | AB57: GRADE 9 | AE57: GRADE 10
C58: DEF | D58: 0 | G58: 0 | J58: 0 | M58: 0 | P58: 0 | S58: 0 | V58: 0 | Y58: 0 | AB58: 0 | AE58: 0
C59: DRIFT | D59: 0 | G59: 0 | J59: 0 | M59: 0 | P59: 0 | S59: 0 | V59: 0 | Y59: 0 | AB59: 0 | AE59: 0
C60: SKILL
A65: TOBI-KADACHI | D65: GRADE 1 | G65: GRADE 2 | J65: GRADE 3 | M65: GRADE 4 | P65: GRADE 5 | S65: GRADE 6 | V65: GRADE 7 | Y65: GRADE 8 | AB65: GRADE 9 | AE65: GRADE 10
C66: DEF | D66: 0 | G66: 0 | J66: 0 | M66: 0 | P66: 0 | S66: 0 | V66: 0 | Y66: 0 | AB66: 0 | AE66: 0
C67: DRIFT | D67: 0 | G67: 0 | J67: 0 | M67: 0 | P67: 0 | S67: 0 | V67: 0 | Y67: 0 | AB67: 0 | AE67: 0
C68: SKILL
A73: PAOLUMU | D73: GRADE 1 | G73: GRADE 2 | J73: GRADE 3 | M73: GRADE 4 | P73: GRADE 5 | S73: GRADE 6 | V73: GRADE 7 | Y73: GRADE 8 | AB73: GRADE 9 | AE73: GRADE 10
C74: DEF | D74: 0 | G74: 0 | J74: 0 | M74: 0 | P74: 0 | S74: 0 | V74: 0 | Y74: 0 | AB74: 0 | AE74: 0
C75: DRIFT | D75: 0 | G75: 0 | J75: 0 | M75: 0 | P75: 0 | S75: 0 | V75: 0 | Y75: 0 | AB75: 0 | AE75: 0
C76: SKILL
...

Sheet Gunlance
A1: IRON | C1: NORMAL | D1: GRADE 1 | G1: GRADE 2 | J1: GRADE 3 | M1: GRADE 4 | P1: GRADE 5 | S1: GRADE 6 | V1: GRADE 7 | Y1: GRADE 8 | AB1: GRADE 9 | AE1: GRADE 10
C2: ATK | D2: 142 | G2: 204 | J2: 294 | M2: 424 | P2: 567 | S2: 737 | V2: 958 | Y2: 1245 | AB2: 1618 | AE2: 2103
C3: NONE | D3: 0 | G3: 0 | J3: 0 | M3: 0 | P3: 0 | S3: 0 | V3: 0 | Y3: 0 | AB3: 0 | AE3: 0
C4: AFN | D4: 0 | G4: 0 | J4: 0 | M4: 0 | P4: 0 | S4: 0 | V4: 0 | Y4: 0 | AB4: 0 | AE4: 0
C5: SKILL
A10: BONE | C10: LONG | D10: GRADE 1 | G10: GRADE 2 | J10: GRADE 3 | M10: GRADE 4 | P10: GRADE 5 | S10: GRADE 6 | V10: GRADE 7 | Y10: GRADE 8 | AB10: GRADE 9 | AE10: GRADE 10
C11: ATK | D11: 142 | G11: 204 | J11: 294 | M11: 424 | P11: 567 | S11: 737 | V11: 958 | Y11: 1245 | AB11: 1618 | AE11: 2103
C12: NONE | D12: 0 | G12: 0 | J12: 0 | M12: 0 | P12: 0 | S12: 0 | V12: 0 | Y12: 0 | AB12: 0 | AE12: 0
C13: AFN | D13: 0 | G13: 0 | J13: 0 | M13: 0 | P13: 0 | S13: 0 | V13: 0 | Y13: 0 | AB13: 0 | AE13: 0
C14: SKILL | M14: Defense Boost | O14: 1 | P14: Defense Boost | R14: 1 | S14: Defense Boost | U14: 1 | V14: Defense Boost | X14: 1 | Y14: Defense Boost | AA14: 2 | AB14: Defense Boost | AD14: 2 | AE14: Defense Boost | AG14: 2
A19: GREAT JAGRAS | C19: NORMAL | D19: GRADE 1 | G19: GRADE 2 | J19: GRADE 3 | M19: GRADE 4 | P19: GRADE 5 | S19: GRADE 6 | V19: GRADE 7 | Y19: GRADE 8 | AB19: GRADE 9 | AE19: GRADE 10
C20: ATK | D20: 123 | G20: 174 | J20: 249 | M20: 355 | P20: 469 | S20: 603 | V20: 775 | Y20: 996 | AB20: 1280 | AE20: 1644
C21: WATER | D21: 34 | G21: 53 | J21: 81 | M21: 122 | P21: 171 | S21: 232 | V21: 313 | Y21: 421 | AB21: 565 | AE21: 754
C22: AFN | D22: 0 | G22: 0 | J22: 0 | M22: 0 | P22: 0 | S22: 0 | V22: 0 | Y22: 0 | AB22: 0 | AE22: 0
C23: SKILL | M23: Health Boost | O23: 1 | P23: Health Boost | R23: 1 | S23: Health Boost | U23: 1 | V23: Health Boost | X23: 1 | Y23: Health Boost | AA23: 2 | AB23: Health Boost | AD23: 2 | AE23: Health Boost | AG23: 2
A28: BARROTH | C28: WIDE | D28: GRADE 1 | G28: GRADE 2 | J28: GRADE 3 | M28: GRADE 4 | P28: GRADE 5 | S28: GRADE 6 | V28: GRADE 7 | Y28: GRADE 8 | AB28: GRADE 9 | AE28: GRADE 10
C29: ATK | D29: 142 | G29: 204 | J29: 294 | M29: 424 | P29: 567 | S29: 737 | V29: 958 | Y29: 1245 | AB29: 1618 | AE29: 2103
C30: NONE | D30: 0 | G30: 0 | J30: 0 | M30: 0 | P30: 0 | S30: 0 | V30: 0 | Y30: 0 | AB30: 0 | AE30: 0
C31: AFN | D31: 0 | G31: 0 | J31: 0 | M31: 0 | P31: 0 | S31: 0 | V31: 0 | Y31: 0 | AB31: 0 | AE31: 0
C32: SKILL | M32: Defense Boost | O32: 1 | P32: Defense Boost | R32: 1 | S32: Defense Boost | U32: 1 | V32: Defense Boost | X32: 1 | Y32: Defense Boost | AA32: 2 | AB32: Defense Boost | AD32: 2 | AE32: Defense Boost | AG32: 2
A37: GREAT GIRROS | C37: NORMAL | D37: GRADE 1 | G37: GRADE 2 | J37: GRADE 3 | M37: GRADE 4 | P37: GRADE 5 | S37: GRADE 6 | V37: GRADE 7 | Y37: GRADE 8 | AB37: GRADE 9 | AE37: GRADE 10
C38: ATK | D38: 142 | G38: 204 | J38: 294 | M38: 424 | P38: 567 | S38: 737 | V38: 958 | Y38: 1245 | AB38: 1618 | AE38: 2103
C39: PARALYSIS | D39: 0 | G39: 0 | J39: 0 | M39: 0 | P39: 0 | S39: 0 | V39: 0 | Y39: 0 | AB39: 0 | AE39: 0
C40: AFN | D40: 0 | G40: 0 | J40: 0 | M40: 0 | P40: 0 | S40: 0 | V40: 0 | Y40: 0 | AB40: 0 | AE40: 0
C41: SKILL
A46: TOBI-KADACHI | C46: LONG | D46: GRADE 1 | G46: GRADE 2 | J46: GRADE 3 | M46: GRADE 4 | P46: GRADE 5 | S46: GRADE 6 | V46: GRADE 7 | Y46: GRADE 8 | AB46: GRADE 9 | AE46: GRADE 10
C47: ATK | D47: 142 | G47: 204 | J47: 294 | M47: 424 | P47: 567 | S47: 737 | V47: 958 | Y47: 1245 | AB47: 1618 | AE47: 2103
C48: THUNDER | D48: 0 | G48: 0 | J48: 0 | M48: 0 | P48: 0 | S48: 0 | V48: 0 | Y48: 0 | AB48: 0 | AE48: 0
C49: AFN | D49: 0 | G49: 0 | J49: 0 | M49: 0 | P49: 0 | S49: 0 | V49: 0 | Y49: 0 | AB49: 0 | AE49: 0
C50: SKILL | M50: Defense Boost | O50: 1 | P50: Defense Boost | R50: 1 | S50: Defense Boost | U50: 1 | V50: Defense Boost | X50: 1 | Y50: Defense Boost | AA50: 2 | AB50: Defense Boost | AD50: 2 | AE50: Defense Boost | AG50: 2
A55: JYURATODUS | C55: WIDE | D55: GRADE 1 | G55: GRADE 2 | J55: GRADE 3 | M55: GRADE 4 | P55: GRADE 5 | S55: GRADE 6 | V55: GRADE 7 | Y55: GRADE 8 | AB55: GRADE 9 | AE55: GRADE 10
C56: ATK | D56: 142 | G56: 204 | J56: 294 | M56: 424 | P56: 567 | S56: 737 | V56: 958 | Y56: 1245 | AB56: 1618 | AE56: 2103
C57: WATER | D57: 0 | G57: 0 | J57: 0 | M57: 0 | P57: 0 | S57: 0 | V57: 0 | Y57: 0 | AB57: 0 | AE57: 0
C58: AFN | D58: 0 | G58: 0 | J58: 0 | M58: 0 | P58: 0 | S58: 0 | V58: 0 | Y58: 0 | AB58: 0 | AE58: 0
C59: SKILL
A64: ANJANATH | C64: NORMAL | D64: GRADE 1 | G64: GRADE 2 | J64: GRADE 3 | M64: GRADE 4 | P64: GRADE 5 | S64: GRADE 6 | V64: GRADE 7 | Y64: GRADE 8 | AB64: GRADE 9 | AE64: GRADE 10
C65: ATK | D65: 142 | G65: 204 | J65: 294 | M65: 424 | P65: 567 | S65: 737 | V65: 958 | Y65: 1245 | AB65: 1618 | AE65: 2103
C66: FIRE | D66: 0 | G66: 0 | J66: 0 | M66: 0 | P66: 0 | S66: 0 | V66: 0 | Y66: 0 | AB66: 0 | AE66: 0
C67: AFN | D67: 0 | G67: 0 | J67: 0 | M67: 0 | P67: 0 | S67: 0 | V67: 0 | Y67: 0 | AB67: 0 | AE67: 0
C68: SKILL | M68: Defense Boost | O68: 1 | P68: Defense Boost | R68: 1 | S68: Defense Boost | U68: 1 | V68: Defense Boost | X68: 1 | Y68: Defense Boost | AA68: 2 | AB68: Defense Boost | AD68: 2 | AE68: Defense Boost | AG68: 2
...

Sheet Lists
B2: Weapon Types | E2: Element Colors | I2: GRADE 1 | J2: GRADE 2 | K2: GRADE 3 | L2: GRADE 4 | M2: GRADE 5 | N2: GRADE 6 | O2: GRADE 7 | P2: GRADE 8 | Q2: GRADE 9 | R2: GRADE 10 | U2: SHELL #
B3: Sword and Shield | E3: NONE | I3: SHELLING | T3: NORMAL | U3: 5
B4: Greadsword | E4: WATER | H4: NORMAL | I4: 42 | J4: 61 | K4: 87 | L4: 126 | M4: 181 | N4: 235 | O4: 306 | P4: 397 | Q4: 516 | R4: 671 | T4: LONG | U4: 3
B5: Hammer | E5: FIRE | H5: LONG | I5: 66 | J5: 96 | K5: 137 | L5: 198 | M5: 284 | N5: 369 | O5: 480 | P5: 624 | Q5: 811 | R5: 1054 | T5: WIDE | U5: 2
B6: Longsword | E6: THUNDER | H6: WIDE | I6: 82 | J6: 119 | K6: 170 | L6: 246 | M6: 353 | N6: 459 | O6: 597 | P6: 775 | Q6: 1007 | R6: 1309
B7: Light Bowgun | E7: DRAGON | I7: CHARGED SHELLING
B8: Bow | E8: POISON | H8: NORMAL | I8: 68 | J8: 98 | K8: 141 | L8: 204 | M8: 293 | N8: 381 | O8: 495 | P8: 643 | Q8: 836 | R8: 1086
B9: Dual Blades | E9: PARALYSIS | H9: LONG | I9: 158 | J9: 228 | K9: 328 | L9: 473 | M9: 680 | N9: 884 | O9: 1149 | P9: 1494 | Q9: 1941 | R9: 2522
B10: Lance | H10: WIDE | I10: 114 | J10: 165 | K10: 236 | L10: 341 | M10: 491 | N10: 638 | O10: 829 | P10: 1078 | Q10: 1400 | R10: 1820
B11: Chargeblade | I11: BURST
B12: Gunlance | H12: NORMAL | I12: 56 | J12: 80 | K12: 114 | L12: 165 | M12: 237 | N12: 308 | O12: 400 | P12: 520 | Q12: 676 | R12: 878
B13: Heavy Bowgun | H13: LONG | I13: 66 | J13: 96 | K13: 137 | L13: 198 | M13: 284 | N13: 369 | O13: 480 | P13: 624 | Q13: 811 | R13: 1054
B14: Switchaxe | H14: WIDE | I14: 72 | J14: 104 | K14: 150 | L14: 216 | M14: 310 | N14: 403 | O14: 524 | P14: 681 | Q14: 885 | R14: 1150
B15: Hunting Horn
A18: WEAPON LISTS
A19: GL
A20: {=_xlfn.UNIQUE(_xlfn._xlws.FILTER(Gunlance!A1:A500,Gunlance!A1:A500<>"",""))} -> IRON
A21: BONE
A22: GREAT JAGRAS
A23: BARROTH
A24: GREAT GIRROS
A25: TOBI-KADACHI
A26: JYURATODUS
A27: ANJANATH
A28: FULGUR ANJANATH
A29: RATHIAN
A30: PINK RATHIAN
A31: GOLD RATHIAN
A32: LEGIANA
... A63: HOPE

Sheet Utility
A1: For Build Current Skills
A2: {=_xlfn.UNIQUE(_xlfn._xlws.FILTER(Build!#REF!, Build!#REF! <> ""))} -> #REF! | B2: =SUMIF(Build!#REF!,Utility!A2,Build!#REF!) -> #REF!
B3: =SUMIF(Build!J30:J30,Utility!A3,Build!M26:M26) -> 0
B4: =SUMIF(Build!J30:J31,Utility!A4,Build!M26:M27) -> 0
B5: =SUMIF(Build!J30:J32,Utility!A5,Build!M26:M28) -> 0
B6: =SUMIF(Build!J26:J27,Utility!A6,Build!M26:M29) -> 0
B7: =SUMIF(Build!J26:J35,Utility!A7,Build!M26:M30) -> 0
B8: =SUMIF(Build!J26:J36,Utility!A8,Build!M26:M31) -> 0
B9: =SUMIF(Build!J26:J37,Utility!A9,Build!M26:M32) -> 0
B10: =SUMIF(Build!J26:J38,Utility!A10,Build!M26:M33) -> 0
B11: =SUMIF(Build!J26:J39,Utility!A11,Build!M26:M34) -> 0
B12: =SUMIF(Build!J26:J34,Utility!A12,Build!M26:M35) -> 0
B13: =SUMIF(Build!J26:J34,Utility!A13,Build!M26:M36) -> 0
B14: =SUMIF(Build!J26:J34,Utility!A14,Build!M26:M37) -> 0
B15: =SUMIF(Build!J26:J34,Utility!A15,Build!M26:M38) -> 0
B16: =SUMIF(Build!J26:J39,Utility!A16,Build!M26:M39) -> 0
B17: =SUMIF(Build!J26:J40,Utility!A17,Build!M26:M40) -> 0
B18: =SUMIF(Build!J26:J41,Utility!A18,Build!M26:M41) -> 0
B19: =SUMIF(Build!J26:J42,Utility!A19,Build!M26:M42) -> 0
B20: =SUMIF(Build!J26:J43,Utility!A20,Build!M26:M43) -> 0
B21: =SUMIF(Build!J26:J44,Utility!A21,Build!M26:M44) -> 0
B22: =SUMIF(Build!J26:J45,Utility!A22,Build!M26:M45) -> 0
B23: =SUMIF(Build!J26:J46,Utility!A23,Build!M26:M46) -> 0
B24: =SUMIF(Build!J26:J47,Utility!A24,Build!M26:M47) -> 0
B25: =SUMIF(Build!J26:J48,Utility!A25,Build!M26:M48) -> 0
B26: =SUMIF(Build!J27:J49,Utility!A26,Build!M27:M49) -> 0
